Workbook
Name TRAINING_UNIT_PRICE: Variables!#REF!
Name UNIT_5: Variables!$J$12
Name Z_E6596C0B_1A16_4C13_A664_892027304A31_.wvu.PrintArea: Financements!$B$1:$T$67
Name Z_EEA24EE8_2525_C446_8B59_1C9C99656C98_.wvu.PrintArea: 'Plan de financement'!$A$1:$G$57
Name Z_EEA24EE8_2525_C446_8B59_1C9C99656C98_.wvu.PrintArea: 'BFR '!$B$26:$O$44
Name UNIT_PRICE_CLIENT_F: Variables!$I$15
Name Statut_JEI: Variables!$C$24
Name UNIT_PRICE_CLIENT_A: Variables!$I$10
Name UNIT_PRICE_DECOUVERTE: Variables!$I$10
Name UNIT_20: Variables!$J$14
Name Z_15B2DCEA_87E0_4C3D_A53F_208BD26E925F_.wvu.PrintArea: Investissements!$B$1:$Q$77
Name Z_8C30E345_2AE0_4C49_8CA3_C007F1DFF339_.wvu.PrintArea: 'Cash Flow'!$B$1:$AF$40
Name Z_E6596C0B_1A16_4C13_A664_892027304A31_.wvu.PrintArea: 'Cash Flow'!$B$1:$AF$40
Name Z_15B2DCEA_87E0_4C3D_A53F_208BD26E925F_.wvu.PrintArea: 'Cash Flow'!$B$1:$AF$40
Name SIZE_LARGE: Variables!$C$35
Name Z_15B2DCEA_87E0_4C3D_A53F_208BD26E925F_.wvu.PrintArea: CR!$B$1:$O$58
Name Taux_de_commission: Variables!$C$11
Name Salaires_Immob_DG: Variables!$C$14
Name Z_8C30E345_2AE0_4C49_8CA3_C007F1DFF339_.wvu.PrintArea: CR!$B$1:$O$58
Name Z_61AF70DF_5A11_444F_A95C_90F81E928498_.wvu.PrintArea: Financements!$B$1:$T$67
Name CONFLUENCE_PRICE: Variables!$F$27
Name GOOGLE_PRICE: Variables!$F$25
Name UNIT_1: Variables!$J$11
Name UNIT_60: Variables!$J$16
Name Impot_sur_sociétés: Variables!$C$19
Name Z_15B2DCEA_87E0_4C3D_A53F_208BD26E925F_.wvu.PrintArea: Bilan!$A$1:$G$57
Name Z_61AF70DF_5A11_444F_A95C_90F81E928498_.wvu.PrintArea: 'BFR '!$B$26:$O$44
Name Salaires_Immob_Prod_Dev: Variables!$C$15
Name Délai_paiement_invest: Variables!$F$18
Name Taux_de_CICE: Variables!$C$10
Name Z_E6596C0B_1A16_4C13_A664_892027304A31_.wvu.PrintArea: Investissements!$B$1:$Q$77
Name SIZE_SMALL: Variables!$C$33
Name Z_8C30E345_2AE0_4C49_8CA3_C007F1DFF339_.wvu.PrintArea: Bilan!$A$1:$G$57
Name Taux_de_TVA_investissement: Variables!$C$20
Name Délai_paiement_ST: Variables!$F$16
Name Z_B9E23C8B_E79A_4E77_BB37_453028BABEDF_.wvu.PrintArea: Financements!$B$1:$H$67
Name Z_E6596C0B_1A16_4C13_A664_892027304A31_.wvu.PrintArea: 'Plan de financement'!$A$1:$G$57
Name UNIT_PRICE_ILLIMITE: Variables!$I$17
Name Z_9F2F25DB_E3B2_4813_9899_141DF1E6770F_.wvu.PrintArea: CR!$B$1:$O$58
Name Z_9F2F25DB_E3B2_4813_9899_141DF1E6770F_.wvu.PrintArea: Investissements!$B$1:$G$78
Name Z_8C30E345_2AE0_4C49_8CA3_C007F1DFF339_.wvu.PrintArea: 'BFR '!$B$26:$O$44
Name Z_8C30E345_2AE0_4C49_8CA3_C007F1DFF339_.wvu.PrintArea: Financements!$B$1:$T$67
Name Inflation_salaires: Variables!$C$12
Name UNIT_PRICE_CLIENT_D: Variables!$I$13
Name inflation_vente: Variables!$I$45
Name EMPLOYEE_KIT_COST: Variables!$C$34
Name UNIT_PRICE_60_UNITE: Variables!$I$16
Name WEBFLOW_PRICING: Variables!$F$31
Name Durée_de_stockage_A: Variables!$F$21
Name Z_9F2F25DB_E3B2_4813_9899_141DF1E6770F_.wvu.PrintArea: Financements!$B$1:$G$67
Name Z_EEA24EE8_2525_C446_8B59_1C9C99656C98_.wvu.PrintArea: Bilan!$A$1:$G$57
Name TJH: #REF!
Name date_début: Variables!$F$5
Name Délai_paiement_Achat: Variables!$F$15
Name Z_8C30E345_2AE0_4C49_8CA3_C007F1DFF339_.wvu.PrintArea: 'Plan de financement'!$A$1:$G$57
Name UNIT_PRICE_CLIENT_B: Variables!$I$11
Name Z_61AF70DF_5A11_444F_A95C_90F81E928498_.wvu.PrintArea: Bilan!$A$1:$G$57
Name wacc: Valorisation!$C$27
Name Délai_encaissement_B: Variables!$F$10
Name Z_61AF70DF_5A11_444F_A95C_90F81E928498_.wvu.PrintArea: 'Cash Flow'!$B$1:$AF$40

Sheet Cover Pres
A1: $^`
H2: BUSINESS PLAN
H3: PLAN D'AFFAIRES
B7: A) ORGANISATION GENERALE
C9: Ce modèle est destiné à permettre de calculer pour un projet les états financiers suivants :
C10: - Compte de résultat
C11: - Plan de trésorerie (cash-flow)
C12: - Bilan
C13: - Valorisation
C15: Les calculs sont réalisés dans plusieurs modules auxquels correspondent les onglets du présent fichier Excel :
C17: - Onglet Variables : Inputs et hypothèses du BP (masse salariale, macroéconomie, délais paiement…)
C18: - Onglet CA : Chiffre d'affaire et Prix de Revient (ventilation et calcul de la marge brute sur coûts variables directs)
C19: - Onglet Personnel : Dimensionnement dans le temps des Ressources Humaines, par fonction clé
C20: - Onglet Charges externes : notamment dépenses de communication et commerciales (hors Personnel)
C21: - Onglet Investissements : décomposition des investissements et de leurs amortissements
C22: - Onglet Financements : structuration des financements (part capital et part endettement)
... C31: 5 de synthèse (Bilan, CR, BFR, Cash Flow, Résumé 4 ans), un de valorisation
B33: B) OPTIONS GRAPHIQUES
C35: Dans tout le modèle le type de trait et la couleur des cellules permettent de connaitre la nature du chiffre indiqué
C37: Les cellules qui incluent des résultats de calcul ou qui viennent
C38: d'autres modules sont dans des cellules de type | I38: xxxx | J38: yyyy | L38: / ! \ ne pas entrer de données dans ces cellules
L39: au risque de corrompre le modèle (chiffres calculés par des formules)
C41: Les totaux de premier niveau sont dans des cellules de type | I41: xxxx | J41: yyyy | L41: " | M41: " | N41: "
C43: Les totaux de deuxième niveau sont dans des cellules de type | I43: xxxx | J43: yyyy | L43: " | M43: " | N43: "
C46: Les cellules qui doivent recueillir des entrées de données sont de type | I46: xxxx | J46: xxxx | L46: données à saisir
C48: Les cellules qui sont logiquement vides
C49: sont de type | L49: Pas de données
C51: Les cellules "contrôle" sont destinées a vérifier la cohérence de certains tableaux | I51: 0 | J51: 0 | L51: si le chiffre est différent de 0
C52: sont de type | I52: check | J52: 0 | L52: il y a un probléme de logique dans le module !
C54: Les cellules où est inclus un commentaire explicatif sont de type
B57: C) PERIODES CONSIDEREES
C59: Le format du modèle couvre 4 ans.
C60: Pour les chiffres découlant des années antérieures, seuls les soldes utiles aux calculs sont repris,
C61: en partant de la liasse fiscale, les onglets Bilan et CR alimentent le BFR et le Cash-Flow
C62: Pour les 2 premières années les calculs sont fait mensuellement ou par trimestre, avec des totaux annuels.

Sheet Variables
B2: INPUTS BUSINESS PLAN
E5: Date début BP | F5: 45658
B7: HYPOTHESES GENERALES | E7: HYPOTHESE D'EXPLOITATION | H7: HYPOTHESE DE MODELE ECONOMIQUE
B8: MASSE SALARIALE | E8: DÉLAIS D'ENCAISSEMENT CLIENTS | F8: en nb de jours | H8: Persona | I8: Prix HT | J8: N° unités | K8: TVA | L8: Prix à l'unité | M8: Description
B9: Taux charges sociales (patronale) | C9: 0.45 | E9: Délai d'encaissement - Court | F9: 0 | H9: Unité de gestion | I9: 1h30
B10: Taux de CICE | C10: 0 | E10: Délai d'encaissement - Moyen | F10: 1 | H10: client A | I10: =(L10/(1+K10))*J10 -> 5 | J10: 1 | K10: 0.1 | L10: 5.5 | M10: drink
B11: Taux de commission | C11: 0.25 | E11: Délai d'encaissement - Long | F11: 1 | H11: client B | I11: =(L11/(1+K11))*J11 -> 9.1818182 | J11: 1 | K11: 0.1 | L11: 10.1 | M11: drink+patisserie ( gouter/ collation)
B12: Inflation salaires | C12: 0.05 | E12: xx | F12: 0 | H12: client C | I12: =(L12/(1+K12))*J12 -> 12.727273 | J12: 1 | K12: 0.1 | L12: 14 | M12: breakfast
B13: Part de salaires immob. R&D | H13: client D | I13: =(L13/(1+K13))*J13 -> 16.363636 | J13: 1 | K13: 0.1 | L13: 18 | M13: lunch
B14: Directeur général | C14: 0 | E14: DÉLAIS DE PAIEMENT FOURNISSEURS | F14: en nb de jours | H14: client E | I14: =(L14/(1+K14))*J14 -> 20.590909 | J14: 1 | K14: 0.1 | L14: 22.65 | M14: brunch (lunch+drink+patisserie)
B15: Effectif - Production & Dev | C15: 0 | E15: Délai de paiement - Court | F15: 30 | I15: =(L15/(1+K15))*J15 -> 0
E16: Délai de paiement - Moyen | F16: 60
E17: Délai de paiement - Long | F17: 90 | H17: Business Days | I17: jours
B18: FISCALITE | E18: xx | F18: 0 | H18: Nombre de jours par an | I18: 365
B19: Impôt sur les Sociétés | C19: 0.25 | H19: Nombre de jours flottants (fermeture) | I19: 10
B20: Taux de TVA investissement | C20: 0.2 | E20: DURÉE DE STOCKAGE | F20: en nb de jours | H20: Nombre de jours ferié | I20: 11
B21: Taux de TVA moyen (alcohol 20%, drinks 10%, food10%) | C21: 0.12 | E21: xx | F21: 0 | H21: Nombre de jours non ouvrés | I21: 52
E22: xx | F22: 0 | H22: nombre de jours de fermeture annuelle | I22: 15
B23: INNOVATION / SUBVENTION
B24: Statut JEI | C24: 0 | E24: PRIX ABONNEMENTS | F24: Prix | H24: Nombre de jours business | I24: =I18-I19-I21-I22 -> 288
B25: Taux Charges Sociales JEI | C25: 0 | F25: 0
B26: Statut CIR | C26: 0 | F26: 0 | H26: Taux de remplissage | I26: %
B27: Taux de CIR | C27: =IF(C26=1,30%,0%) -> 0 | F27: 0 | H27: Remplissage minimal à atteindre | I27: 1
F28: 0 | H28: Remplissage Optimal | I28: 1.5
B29: KIT Collaborateur | C29: Prix | F29: 0
B30: xxx | C30: 0 | F30: 0
B31: xxx | C31: 0 | F31: 0 | H31: Nombre de couverts | I31: Places
B32: xxx | C32: 0 | F32: 0 | H32: Interieur | I32: 18
B33: xxx | C33: 0 | H33: Terssase | I33: 0
B34: Total Kit Collaborateur | C34: =SUM(C30:C33) -> 0 | H34: T.estivale | I34: 24
H36: Services | I36: Min | J36: AVG | K36: Max
H37: Brunch | I37: 17 | J37: 23 | L37: 29
H38: Coallation | I38: 5 | J38: 8 | L38: 14
H39: Livraison | I39: 17 | J39: 23 | L39: 29
H40: Emporter (boisson) | I40: 5 | J40: 8 | L40: 14
H41: Epicerie | I41: 5 | J41: 10 | L41: 15
H42: Traiteur | I42: 200 | J42: 300 | L42: 500
H44: Variables | I44: %
H45: Inflation vente | I45: 0.03

Sheet Insights surplace
A2: OFFRE RESTAURATION SUR PLACE ET A EMPORTER | M2: capacité: | N2: 18 assises
C3: Heure-Jour | D3: 2025 | K3: 2026 | R3: 2027
C4: % remplissage horaire | D4: 8h30-10h | E4: 10h-11h30 | F4: 11h30-13 | G4: 13h-14h30 | H4: 14h30-16h | I4: 16h-17h30 | K4: 8h30-10h | L4: 10h-11h30 | M4: 11h30-13 | N4: 13h-14h30 | O4: 14h30-16h | P4: 16h-17h30 | R4: 8h30-10h | S4: 10h-11h30 | T4: 11h30-13 | U4: 13h-14h30 | V4: 14h30-16h | W4: 16h-17h30
C5: client A | D5: 0.3 | E5: 0.1 | G5: 0.05 | H5: 0.3 | I5: 0.4 | K5: 0.3 | L5: 0.1 | N5: 0.05 | O5: 0.3 | P5: 0.4 | R5: 0.3 | S5: 0.1 | U5: 0.05 | V5: 0.3 | W5: 0.4
C6: client B | D6: 0.4 | E6: 0.35 | G6: 0.05 | H6: 0.5 | I6: 0.55 | K6: 0.4 | L6: 0.35 | N6: 0.05 | O6: 0.5 | P6: 0.55 | R6: 0.4 | S6: 0.35 | U6: 0.05 | V6: 0.5 | W6: 0.55
C7: client C | D7: 0.15 | E7: 0.3 | F7: 0.05 | G7: 0 | H7: 0 | I7: 0.05 | K7: 0.15 | L7: 0.3 | M7: 0.05 | N7: 0 | O7: 0 | P7: 0.05 | R7: 0.15 | S7: 0.3 | T7: 0.05 | U7: 0 | V7: 0 | W7: 0.05
C8: client D | D8: 0.15 | E8: 0.15 | F8: 0.55 | G8: 0.6 | H8: 0.1 | I8: 0 | K8: 0.15 | L8: 0.15 | M8: 0.55 | N8: 0.6 | O8: 0.1 | P8: 0 | R8: 0.15 | S8: 0.15 | T8: 0.55 | U8: 0.6 | V8: 0.1 | W8: 0
C9: client E | E9: 0.2 | F9: 0.4 | G9: 0.3 | H9: 0.1 | L9: 0.2 | M9: 0.4 | N9: 0.3 | O9: 0.1 | S9: 0.2 | T9: 0.4 | U9: 0.3 | V9: 0.1
D11: =SUM(D5:D10) -> 1 | E11: =SUM(E5:E10) -> 1.1 | F11: =SUM(F5:F10) -> 1 | G11: =SUM(G5:G10) -> 1 | H11: =SUM(H5:H10) -> 1 | I11: =SUM(I5:I10) -> 1 | K11: =SUM(K5:K10) -> 1 | L11: =SUM(L5:L10) -> 1.1 | M11: =SUM(M5:M10) -> 1 | N11: =SUM(N5:N10) -> 1 | O11: =SUM(O5:O10) -> 1 | P11: =SUM(P5:P10) -> 1 | R11: =SUM(R5:R10) -> 1 | S11: =SUM(S5:S10) -> 1.1 | T11: =SUM(T5:T10) -> 1 | U11: =SUM(U5:U10) -> 1 | V11: =SUM(V5:V10) -> 1 | W11: =SUM(W5:W10) -> 1
C14: Heure-Jour | D14: 2025 | K14: 2026 | R14: 2027
D15: 8h30-10h | E15: 10h-11h30 | F15: 11h30-13 | G15: 13h-14h30 | H15: 14h30-16h | I15: 16h-17h30 | K15: 8h30-10h | L15: 10h-11h30 | M15: 11h30-13 | N15: 13h-14h30 | O15: 14h30-16h | P15: 16h-17h30 | R15: 8h30-10h | S15: 10h-11h30 | T15: 11h30-13 | U15: 13h-14h30 | V15: 14h30-16h | W15: 16h-17h30
C16: Nombre de clients | D16: 10 | E16: 15 | F16: 18 | G16: 20 | H16: 15 | I16: 15 | K16: 11 | L16: 16 | M16: 18 | N16: 18 | O16: 17 | P16: 14 | R16: 11 | S16: 16 | T16: 18 | U16: 18 | V16: 17 | W16: 14
C17: client A | D17: =ROUND( D$16*D5,0) -> 3 | E17: =ROUND( E$16*E5,0) -> 2 | F17: =ROUND( F$16*F5,0) -> 0 | G17: =ROUND( G$16*G5,0) -> 1 | H17: =ROUND( H$16*H5,0) -> 5 | I17: =ROUND( I$16*I5,0) -> 6 | K17: =ROUND( K$16*K5,0) -> 3 | L17: =ROUND( L$16*L5,0) -> 2 | M17: =ROUND( M$16*M5,0) -> 0 | N17: =ROUND( N$16*N5,0) -> 1 | O17: =ROUND( O$16*O5,0) -> 5 | P17: =ROUND( P$16*P5,0) -> 6 | R17: =ROUND( R$16*R5,0) -> 3 | S17: =ROUND( S$16*S5,0) -> 2 | T17: =ROUND( T$16*T5,0) -> 0 | U17: =ROUND( U$16*U5,0) -> 1 | V17: =ROUND( V$16*V5,0) -> 5 | W17: =ROUND( W$16*W5,0) -> 6
C18: client B | D18: =ROUND( D$16*D6,0) -> 4 | E18: =ROUND( E$16*E6,0) -> 5 | F18: =ROUND( F$16*F6,0) -> 0 | G18: =ROUND( G$16*G6,0) -> 1 | H18: =ROUND( H$16*H6,0) -> 8 | I18: =ROUND( I$16*I6,0) -> 8 | K18: =ROUND( K$16*K6,0) -> 4 | L18: =ROUND( L$16*L6,0) -> 6 | M18: =ROUND( M$16*M6,0) -> 0 | N18: =ROUND( N$16*N6,0) -> 1 | O18: =ROUND( O$16*O6,0) -> 9 | P18: 9 | R18: =ROUND( R$16*R6,0) -> 4 | S18: =ROUND( S$16*S6,0) -> 6 | T18: =ROUND( T$16*T6,0) -> 0 | U18: =ROUND( U$16*U6,0) -> 1 | V18: =ROUND( V$16*V6,0) -> 9 | W18: =ROUND( W$16*W6,0) -> 8
C19: client C | D19: =ROUND( D$16*D7,0) -> 2 | E19: =ROUND( E$16*E7,0) -> 5 | F19: =ROUND( F$16*F7,0) -> 1 | G19: =ROUND( G$16*G7,0) -> 0 | H19: =ROUND( H$16*H7,0) -> 0 | I19: =ROUND( I$16*I7,0) -> 1 | K19: =ROUND( K$16*K7,0) -> 2 | L19: =ROUND( L$16*L7,0) -> 5 | M19: =ROUND( M$16*M7,0) -> 1 | N19: =ROUND( N$16*N7,0) -> 0 | O19: =ROUND( O$16*O7,0) -> 0 | P19: 3 | R19: =ROUND( R$16*R7,0) -> 2 | S19: =ROUND( S$16*S7,0) -> 5 | T19: =ROUND( T$16*T7,0) -> 1 | U19: =ROUND( U$16*U7,0) -> 0 | V19: =ROUND( V$16*V7,0) -> 0 | W19: =ROUND( W$16*W7,0) -> 1
C20: client D | D20: =ROUND( D$16*D8,0) -> 2 | E20: =ROUND( E$16*E8,0) -> 2 | F20: =ROUND( F$16*F8,0) -> 10 | G20: =ROUND( G$16*G8,0) -> 12 | H20: =ROUND( H$16*H8,0) -> 2 | I20: =ROUND( I$16*I8,0) -> 0 | K20: =ROUND( K$16*K8,0) -> 2 | L20: =ROUND( L$16*L8,0) -> 2 | M20: =ROUND( M$16*M8,0) -> 10 | N20: =ROUND( N$16*N8,0) -> 11 | O20: =ROUND( O$16*O8,0) -> 2 | P20: =ROUND( P$16*P8,0) -> 0 | R20: =ROUND( R$16*R8,0) -> 2 | S20: =ROUND( S$16*S8,0) -> 2 | T20: =ROUND( T$16*T8,0) -> 10 | U20: =ROUND( U$16*U8,0) -> 11 | V20: =ROUND( V$16*V8,0) -> 2 | W20: =ROUND( W$16*W8,0) -> 0
C21: client E | D21: =ROUND( D$16*D9,0) -> 0 | E21: =ROUND( E$16*E9,0) -> 3 | F21: =ROUND( F$16*F9,0) -> 7 | G21: =ROUND( G$16*G9,0) -> 6 | H21: =ROUND( H$16*H9,0) -> 2 | I21: =ROUND( I$16*I9,0) -> 0 | K21: =ROUND( K$16*K9,0) -> 0 | L21: =ROUND( L$16*L9,0) -> 3 | M21: =ROUND( M$16*M9,0) -> 7 | N21: =ROUND( N$16*N9,0) -> 5 | O21: =ROUND( O$16*O9,0) -> 2 | P21: =ROUND( P$16*P9,0) -> 0 | R21: =ROUND( R$16*R9,0) -> 0 | S21: =ROUND( S$16*S9,0) -> 3 | T21: =ROUND( T$16*T9,0) -> 7 | U21: =ROUND( U$16*U9,0) -> 5 | V21: =ROUND( V$16*V9,0) -> 2 | W21: =ROUND( W$16*W9,0) -> 0
D23: =SUM(D17:D22) -> 11 | E23: =SUM(E17:E21) -> 17 | F23: =SUM(F17:F22) -> 18 | G23: =SUM(G17:G22) -> 20 | H23: =SUM(H17:H22) -> 17 | I23: =SUM(I17:I22) -> 15 | K23: =SUM(K17:K22) -> 11 | L23: =SUM(L17:L22) -> 18 | M23: =SUM(M17:M22) -> 18 | N23: =SUM(N17:N22) -> 18 | O23: =SUM(O17:O22) -> 18 | P23: =SUM(P17:P22) -> 18 | R23: =SUM(R17:R22) -> 11 | S23: =SUM(S17:S22) -> 18 | T23: =SUM(T17:T22) -> 18 | U23: =SUM(U17:U22) -> 18 | V23: =SUM(V17:V22) -> 18 | W23: =SUM(W17:W22) -> 15
D25: 2025 | AC25: 2026 | BB25: 2027
C26: jour/mois | D26: mardi | E26: mercredi | F26: jeudi | G26: vendredi | H26: samedi | I26: dimanche | J26: mardi | K26: mercredi | L26: jeudi | M26: vendredi | N26: samedi | O26: dimanche | P26: mardi | Q26: mercredi | R26: jeudi | S26: vendredi | T26: samedi | U26: dimanche | V26: mardi | W26: mercredi | X26: jeudi | Y26: vendredi | Z26: samedi | AA26: dimanche | AC26: mardi | AD26: mercredi | AE26: jeudi | AF26: vendredi | AG26: samedi | AH26: dimanche | AI26: mardi | AJ26: mercredi | AK26: jeudi | AL26: vendredi | AM26: samedi | AN26: dimanche | AO26: mardi | AP26: mercredi | AQ26: jeudi | AR26: vendredi | AS26: samedi | AT26: dimanche | AU26: mardi | AV26: mercredi | AW26: jeudi | AX26: vendredi | AY26: samedi | AZ26: dimanche | BB26: mardi | BC26: mercredi | BD26: jeudi | BE26: vendredi | BF26: samedi | BG26: dimanche | BH26: mardi | BI26: mercredi | BJ26: jeudi | BK26: vendredi | BL26: samedi | BM26: dimanche | BN26: mardi | BO26: mercredi | BP26: jeudi | BQ26: vendredi | BR26: samedi | BS26: dimanche | BT26: mardi | BU26: mercredi | BV26: jeudi | BW26: vendredi | BX26: samedi | BY26: dimanche
D27: 1 | E27: 2 | F27: 3 | G27: 4 | H27: 5 | I27: 6 | J27: 7 | K27: 8 | L27: 9 | M27: 10 | N27: 11 | O27: 12 | P27: 13 | Q27: 14 | R27: 15 | S27: 16 | T27: 17 | U27: 18 | V27: 19 | W27: 20 | X27: 21 | Y27: 22 | Z27: 23 | AA27: 24 | AC27: 1 | AD27: 2 | AE27: 3 | AF27: 4 | AG27: 5 | AH27: 6 | AI27: 7 | AJ27: 8 | AK27: 9 | AL27: 10 | AM27: 11 | AN27: 12 | AO27: 13 | AP27: 14 | AQ27: 15 | AR27: 16 | AS27: 17 | AT27: 18 | AU27: 19 | AV27: 20 | AW27: 21 | AX27: 22 | AY27: 23 | AZ27: 24 | BB27: 1 | BC27: 2 | BD27: 3 | BE27: 4 | BF27: 5 | BG27: 6 | BH27: 7 | BI27: 8 | BJ27: 9 | BK27: 10 | BL27: 11 | BM27: 12 | BN27: 13 | BO27: 14 | BP27: 15 | BQ27: 16 | BR27: 17 | BS27: 18 | BT27: 19 | BU27: 20 | BV27: 21 | BW27: 22 | BX27: 23 | BY27: 24
C28: % remplissage journalier | D28: 0.5 | E28: 0.5 | F28: 0.6 | G28: 0.7 | H28: 0.85 | I28: 0.9 | J28: 0.6 | K28: 0.7 | L28: 0.7 | M28: 0.75 | N28: 0.85 | O28: 0.95 | P28: 0.6 | Q28: 0.7 | R28: 0.7 | S28: 0.85 | T28: 0.9 | U28: 0.9 | V28: 0.6 | W28: 0.7 | X28: 0.8 | Y28: 0.9 | Z28: 1 | AA28: 1 | AC28: 0.7 | AD28: 0.7 | AE28: 0.7 | AF28: 0.9 | AG28: 1 | AH28: 1 | AI28: 0.7 | AJ28: 0.7 | AK28: 0.7 | AL28: 0.9 | AM28: 1 | AN28: 1 | AO28: 0.7 | AP28: 0.7 | AQ28: 0.7 | AR28: 0.9 | AS28: 1 | AT28: 1 | AU28: 0.7 | AV28: 0.7 | AW28: 0.7 | AX28: 0.9 | AY28: 1 | AZ28: 1 | BB28: 0.7 | BC28: 0.7 | BD28: 0.7 | BE28: 0.9 | BF28: 1 | BG28: 1 | BH28: 0.7 | BI28: 0.7 | BJ28: 0.8 | BK28: 1 | BL28: 1 | BM28: 1 | BN28: 0.8 | BO28: 0.8 | BP28: 0.8 | BQ28: 1 | BR28: 1 | BS28: 1 | BT28: 0.8 | BU28: 0.8 | BV28: 0.8 | BW28: 1 | BX28: 1 | BY28: 1
C29: client A | D29: =ROUND(SUM($D17:$I17)*D$28,0) -> 9 | E29: =ROUND(SUM($D17:$I17)*E$28,0) -> 9 | F29: =ROUND(SUM($D17:$I17)*F$28,0) -> 10 | G29: =ROUND(SUM($D17:$I17)*G$28,0) -> 12 | H29: =ROUND(SUM($D17:$I17)*H$28,0) -> 14 | I29: =ROUND(SUM($D17:$I17)*I$28,0) -> 15 | J29: =ROUND(SUM($D17:$I17)*J$28,0) -> 10 | K29: =ROUND(SUM($D17:$I17)*K$28,0) -> 12 | ... AA29: =ROUND(SUM($D17:$I17)*AA$28,0) -> 17 | AC29: =ROUND(SUM($K17:$P17)*AC$28,0) -> 12 | AD29: =ROUND(SUM($K17:$P17)*AD$28,0) -> 12 | AE29: =ROUND(SUM($K17:$P17)*AE$28,0) -> 12 | AF29: =ROUND(SUM($K17:$P17)*AF$28,0) -> 15 | AG29: =ROUND(SUM($K17:$P17)*AG$28,0) -> 17 | AH29: =ROUND(SUM($K17:$P17)*AH$28,0) -> 17 | AI29: =ROUND(SUM($K17:$P17)*AI$28,0) -> 12 | AJ29: =ROUND(SUM($K17:$P17)*AJ$28,0) -> 12 | ... AZ29: =ROUND(SUM($K17:$P17)*AZ$28,0) -> 17 | BB29: =ROUND(SUM($R17:$W17)*BB$28,0) -> 12 | BC29: =ROUND(SUM($R17:$W17)*BC$28,0) -> 12 | BD29: =ROUND(SUM($R17:$W17)*BD$28,0) -> 12 | BE29: =ROUND(SUM($R17:$W17)*BE$28,0) -> 15 | BF29: =ROUND(SUM($R17:$W17)*BF$28,0) -> 17 | BG29: =ROUND(SUM($R17:$W17)*BG$28,0) -> 17 | BH29: =ROUND(SUM($R17:$W17)*BH$28,0) -> 12 | BI29: =ROUND(SUM($R17:$W17)*BI$28,0) -> 12 | ... BY29: =ROUND(SUM($R17:$W17)*BY$28,0) -> 17
C30: client B | D30: =ROUND(SUM($D18:$I18)*D$28,0) -> 13 | E30: =ROUND(SUM($D18:$I18)*E$28,0) -> 13 | F30: =ROUND(SUM($D18:$I18)*F$28,0) -> 16 | G30: =ROUND(SUM($D18:$I18)*G$28,0) -> 18 | H30: =ROUND(SUM($D18:$I18)*H$28,0) -> 22 | I30: =ROUND(SUM($D18:$I18)*I$28,0) -> 23 | J30: =ROUND(SUM($D18:$I18)*J$28,0) -> 16 | K30: =ROUND(SUM($D18:$I18)*K$28,0) -> 18 | ... AA30: =ROUND(SUM($D18:$I18)*AA$28,0) -> 26 | AC30: =ROUND(SUM($K18:$P18)*AC$28,0) -> 20 | AD30: =ROUND(SUM($K18:$P18)*AD$28,0) -> 20 | AE30: =ROUND(SUM($K18:$P18)*AE$28,0) -> 20 | AF30: =ROUND(SUM($K18:$P18)*AF$28,0) -> 26 | AG30: =ROUND(SUM($K18:$P18)*AG$28,0) -> 29 | AH30: =ROUND(SUM($K18:$P18)*AH$28,0) -> 29 | AI30: =ROUND(SUM($K18:$P18)*AI$28,0) -> 20 | AJ30: =ROUND(SUM($K18:$P18)*AJ$28,0) -> 20 | ... AZ30: =ROUND(SUM($K18:$P18)*AZ$28,0) -> 29 | BB30: =ROUND(SUM($R18:$W18)*BB$28,0) -> 20 | BC30: =ROUND(SUM($R18:$W18)*BC$28,0) -> 20 | BD30: =ROUND(SUM($R18:$W18)*BD$28,0) -> 20 | BE30: =ROUND(SUM($R18:$W18)*BE$28,0) -> 25 | BF30: =ROUND(SUM($R18:$W18)*BF$28,0) -> 28 | BG30: =ROUND(SUM($R18:$W18)*BG$28,0) -> 28 | BH30: =ROUND(SUM($R18:$W18)*BH$28,0) -> 20 | BI30: =ROUND(SUM($R18:$W18)*BI$28,0) -> 20 | ... BY30: =ROUND(SUM($R18:$W18)*BY$28,0) -> 28
C31: client C | D31: =ROUND(SUM($D19:$I19)*D$28,0) -> 5 | E31: =ROUND(SUM($D19:$I19)*E$28,0) -> 5 | F31: =ROUND(SUM($D19:$I19)*F$28,0) -> 5 | G31: =ROUND(SUM($D19:$I19)*G$28,0) -> 6 | H31: =ROUND(SUM($D19:$I19)*H$28,0) -> 8 | I31: =ROUND(SUM($D19:$I19)*I$28,0) -> 8 | J31: =ROUND(SUM($D19:$I19)*J$28,0) -> 5 | K31: =ROUND(SUM($D19:$I19)*K$28,0) -> 6 | ... AA31: =ROUND(SUM($D19:$I19)*AA$28,0) -> 9 | AC31: =ROUND(SUM($K19:$P19)*AC$28,0) -> 8 | AD31: =ROUND(SUM($K19:$P19)*AD$28,0) -> 8 | AE31: =ROUND(SUM($K19:$P19)*AE$28,0) -> 8 | AF31: =ROUND(SUM($K19:$P19)*AF$28,0) -> 10 | AG31: =ROUND(SUM($K19:$P19)*AG$28,0) -> 11 | AH31: =ROUND(SUM($K19:$P19)*AH$28,0) -> 11 | AI31: =ROUND(SUM($K19:$P19)*AI$28,0) -> 8 | AJ31: =ROUND(SUM($K19:$P19)*AJ$28,0) -> 8 | ... AZ31: =ROUND(SUM($K19:$P19)*AZ$28,0) -> 11 | BB31: =ROUND(SUM($R19:$W19)*BB$28,0) -> 6 | BC31: =ROUND(SUM($R19:$W19)*BC$28,0) -> 6 | BD31: =ROUND(SUM($R19:$W19)*BD$28,0) -> 6 | BE31: =ROUND(SUM($R19:$W19)*BE$28,0) -> 8 | BF31: =ROUND(SUM($R19:$W19)*BF$28,0) -> 9 | BG31: =ROUND(SUM($R19:$W19)*BG$28,0) -> 9 | BH31: =ROUND(SUM($R19:$W19)*BH$28,0) -> 6 | BI31: =ROUND(SUM($R19:$W19)*BI$28,0) -> 6 | ... BY31: =ROUND(SUM($R19:$W19)*BY$28,0) -> 9
C32: client D | D32: =ROUND(SUM($D20:$I20)*D$28,0) -> 14 | E32: =ROUND(SUM($D20:$I20)*E$28,0) -> 14 | F32: =ROUND(SUM($D20:$I20)*F$28,0) -> 17 | G32: =ROUND(SUM($D20:$I20)*G$28,0) -> 20 | H32: =ROUND(SUM($D20:$I20)*H$28,0) -> 24 | I32: =ROUND(SUM($D20:$I20)*I$28,0) -> 25 | J32: =ROUND(SUM($D20:$I20)*J$28,0) -> 17 | K32: =ROUND(SUM($D20:$I20)*K$28,0) -> 20 | ... AA32: =ROUND(SUM($D20:$I20)*AA$28,0) -> 28 | AC32: =ROUND(SUM($K20:$P20)*AC$28,0) -> 19 | AD32: =ROUND(SUM($K20:$P20)*AD$28,0) -> 19 | AE32: =ROUND(SUM($K20:$P20)*AE$28,0) -> 19 | AF32: =ROUND(SUM($K20:$P20)*AF$28,0) -> 24 | AG32: =ROUND(SUM($K20:$P20)*AG$28,0) -> 27 | AH32: =ROUND(SUM($K20:$P20)*AH$28,0) -> 27 | AI32: =ROUND(SUM($K20:$P20)*AI$28,0) -> 19 | AJ32: =ROUND(SUM($K20:$P20)*AJ$28,0) -> 19 | ... AZ32: =ROUND(SUM($K20:$P20)*AZ$28,0) -> 27 | BB32: =ROUND(SUM($R20:$W20)*BB$28,0) -> 19 | BC32: =ROUND(SUM($R20:$W20)*BC$28,0) -> 19 | BD32: =ROUND(SUM($R20:$W20)*BD$28,0) -> 19 | BE32: =ROUND(SUM($R20:$W20)*BE$28,0) -> 24 | BF32: =ROUND(SUM($R20:$W20)*BF$28,0) -> 27 | BG32: =ROUND(SUM($R20:$W20)*BG$28,0) -> 27 | BH32: =ROUND(SUM($R20:$W20)*BH$28,0) -> 19 | BI32: =ROUND(SUM($R20:$W20)*BI$28,0) -> 19 | ... BY32: =ROUND(SUM($R20:$W20)*BY$28,0) -> 27
C33: client E | D33: =ROUND(SUM($D21:$I21)*D$28,0) -> 9 | E33: =ROUND(SUM($D21:$I21)*E$28,0) -> 9 | F33: =ROUND(SUM($D21:$I21)*F$28,0) -> 11 | G33: =ROUND(SUM($D21:$I21)*G$28,0) -> 13 | H33: =ROUND(SUM($D21:$I21)*H$28,0) -> 15 | I33: =ROUND(SUM($D21:$I21)*I$28,0) -> 16 | J33: =ROUND(SUM($D21:$I21)*J$28,0) -> 11 | K33: =ROUND(SUM($D21:$I21)*K$28,0) -> 13 | ... AA33: =ROUND(SUM($D21:$I21)*AA$28,0) -> 18 | AC33: =ROUND(SUM($K21:$P21)*AC$28,0) -> 12 | AD33: =ROUND(SUM($K21:$P21)*AD$28,0) -> 12 | AE33: =ROUND(SUM($K21:$P21)*AE$28,0) -> 12 | AF33: =ROUND(SUM($K21:$P21)*AF$28,0) -> 15 | AG33: =ROUND(SUM($K21:$P21)*AG$28,0) -> 17 | AH33: =ROUND(SUM($K21:$P21)*AH$28,0) -> 17 | AI33: =ROUND(SUM($K21:$P21)*AI$28,0) -> 12 | AJ33: =ROUND(SUM($K21:$P21)*AJ$28,0) -> 12 | ... AZ33: =ROUND(SUM($K21:$P21)*AZ$28,0) -> 17 | BB33: =ROUND(SUM($R21:$W21)*BB$28,0) -> 12 | BC33: =ROUND(SUM($R21:$W21)*BC$28,0) -> 12 | BD33: =ROUND(SUM($R21:$W21)*BD$28,0) -> 12 | BE33: =ROUND(SUM($R21:$W21)*BE$28,0) -> 15 | BF33: =ROUND(SUM($R21:$W21)*BF$28,0) -> 17 | BG33: =ROUND(SUM($R21:$W21)*BG$28,0) -> 17 | BH33: =ROUND(SUM($R21:$W21)*BH$28,0) -> 12 | BI33: =ROUND(SUM($R21:$W21)*BI$28,0) -> 12 | ... BY33: =ROUND(SUM($R21:$W21)*BY$28,0) -> 17
AC34: =ROUND(SUM($K22:$P22)*AC$28,0) -> 0 | AD34: =ROUND(SUM($K22:$P22)*AD$28,0) -> 0 | AE34: =ROUND(SUM($K22:$P22)*AE$28,0) -> 0 | AF34: =ROUND(SUM($K22:$P22)*AF$28,0) -> 0 | AG34: =ROUND(SUM($K22:$P22)*AG$28,0) -> 0 | AH34: =ROUND(SUM($K22:$P22)*AH$28,0) -> 0 | AI34: =ROUND(SUM($K22:$P22)*AI$28,0) -> 0 | AJ34: =ROUND(SUM($K22:$P22)*AJ$28,0) -> 0 | ... AZ34: =ROUND(SUM($K22:$P22)*AZ$28,0) -> 0 | BB34: =ROUND(SUM($R22:$W22)*BB$28,0) -> 0 | BC34: =ROUND(SUM($R22:$W22)*BC$28,0) -> 0 | BD34: =ROUND(SUM($R22:$W22)*BD$28,0) -> 0 | BE34: =ROUND(SUM($R22:$W22)*BE$28,0) -> 0 | BF34: =ROUND(SUM($R22:$W22)*BF$28,0) -> 0 | BG34: =ROUND(SUM($R22:$W22)*BG$28,0) -> 0 | BH34: =ROUND(SUM($R22:$W22)*BH$28,0) -> 0 | BI34: =ROUND(SUM($R22:$W22)*BI$28,0) -> 0 | ... BY34: =ROUND(SUM($R22:$W22)*BY$28,0) -> 0
D35: =SUM(D29:D34) -> 50 | E35: =SUM(E29:E34) -> 50 | F35: =SUM(F29:F34) -> 59 | G35: =SUM(G29:G34) -> 69 | H35: =SUM(H29:H34) -> 83 | I35: =SUM(I29:I34) -> 87 | J35: =SUM(J29:J34) -> 59 | K35: =SUM(K29:K34) -> 69 | ... AA35: =SUM(AA29:AA34) -> 98 | AC35: =SUM(AC29:AC34) -> 71 | AD35: =SUM(AD29:AD34) -> 71 | AE35: =SUM(AE29:AE34) -> 71 | AF35: =SUM(AF29:AF34) -> 90 | AG35: =SUM(AG29:AG34) -> 101 | AH35: =SUM(AH29:AH34) -> 101 | AI35: =SUM(AI29:AI34) -> 71 | AJ35: =SUM(AJ29:AJ34) -> 71 | ... AZ35: =SUM(AZ29:AZ34) -> 101 | BB35: =SUM(BB29:BB34) -> 69 | BC35: =SUM(BC29:BC34) -> 69 | BD35: =SUM(BD29:BD34) -> 69 | BE35: =SUM(BE29:BE34) -> 87 | BF35: =SUM(BF29:BF34) -> 98 | BG35: =SUM(BG29:BG34) -> 98 | BH35: =SUM(BH29:BH34) -> 69 | BI35: =SUM(BI29:BI34) -> 69 | ... BY35: =SUM(BY29:BY34) -> 98
C38: Evolution des mois
D39: 2025 | P39: 2026 | AB39: 2027 | AN39: 2028
C40: Mois | D40: 1 | E40: 2 | F40: 3 | G40: 4 | H40: 5 | I40: 6 | J40: 7 | K40: 8 | L40: 9 | M40: 10 | N40: 11 | O40: 12 | P40: 1 | Q40: 2 | R40: 3 | S40: 4 | T40: 5 | U40: 6 | V40: 7 | W40: 8 | X40: 9 | Y40: 10 | Z40: 11 | AA40: 12 | AB40: 1 | AC40: 2 | AD40: 3 | AE40: 4 | AF40: 5 | AG40: 6 | AH40: 7 | AI40: 8 | AJ40: 9 | AK40: 10 | AL40: 11 | AM40: 12 | AN40: 1 | AO40: 2 | AP40: 3 | AQ40: 4 | AR40: 5 | AS40: 6 | AT40: 7 | AU40: 8 | AV40: 9 | AW40: 10 | AX40: 11 | AY40: 12
C41: % remplissage mensuel | D41: 0.5 | E41: 0.6 | F41: 0.65 | G41: 0.7 | H41: 0.85 | I41: 1 | J41: 1.1 | K41: 1.1 | L41: 1 | M41: 0.85 | N41: 0.8 | O41: 0.55 | P41: 0.5 | Q41: 0.5 | R41: 0.55 | S41: 0.7 | T41: 0.7 | U41: 1 | V41: 1.1 | W41: 1.1 | X41: 1 | Y41: 0.7 | Z41: 0.6 | AA41: 0.5 | AB41: 0.5 | AC41: 0.5 | AD41: 0.5 | AE41: 0.7 | AF41: 0.7 | AG41: 1 | AH41: 1.1 | AI41: 1.1 | AJ41: 1 | AK41: 0.7 | AL41: 0.6 | AM41: 0.4 | AN41: 0.6 | AO41: 0.65 | AP41: 0.7 | AQ41: 0.75 | AR41: 0.8 | AS41: 1.1 | AT41: 1.2 | AU41: 1.1 | AV41: 1 | AW41: 0.8 | AX41: 0.65 | AY41: 0.5
C42: client A | D42: =ROUND(SUM($D29:$AA29)*D$41,0) -> 155 | E42: =ROUND(SUM($D29:$AA29)*E$41,0) -> 185 | F42: =ROUND(SUM($D29:$AA29)*F$41,0) -> 201 | G42: =ROUND(SUM($D29:$AA29)*G$41,0) -> 216 | H42: =ROUND(SUM($D29:$AA29)*H$41,0) -> 263 | I42: =ROUND(SUM($D29:$AA29)*I$41,0) -> 309 | J42: =ROUND(SUM($D29:$AA29)*J$41,0) -> 340 | K42: =ROUND(SUM($D29:$AA29)*K$41,0) -> 340 | ... O42: =ROUND(SUM($D29:$AA29)*O$41,0) -> 170 | P42: =ROUND(SUM($AC29:$AZ29)*P$41,0) -> 170 | Q42: =ROUND(SUM($AC29:$AZ29)*Q$41,0) -> 170 | R42: =ROUND(SUM($AC29:$AZ29)*R$41,0) -> 187 | S42: =ROUND(SUM($AC29:$AZ29)*S$41,0) -> 238 | T42: =ROUND(SUM($AC29:$AZ29)*T$41,0) -> 238 | U42: =ROUND(SUM($AC29:$AZ29)*U$41,0) -> 340 | V42: =ROUND(SUM($AC29:$AZ29)*V$41,0) -> 374 | W42: =ROUND(SUM($AC29:$AZ29)*W$41,0) -> 374 | ... AA42: =ROUND(SUM($AC29:$AZ29)*AA$41,0) -> 170 | AB42: =ROUND(SUM($BB29:$BY29)*AB$41,0) -> 180 | AC42: =ROUND(SUM($BB29:$BY29)*AC$41,0) -> 180 | AD42: =ROUND(SUM($BB29:$BY29)*AD$41,0) -> 180 | AE42: =ROUND(SUM($BB29:$BY29)*AE$41,0) -> 252 | AF42: =ROUND(SUM($BB29:$BY29)*AF$41,0) -> 252 | AG42: =ROUND(SUM($BB29:$BY29)*AG$41,0) -> 360 | AH42: =ROUND(SUM($BB29:$BY29)*AH$41,0) -> 396 | AI42: =ROUND(SUM($BB29:$BY29)*AI$41,0) -> 396 | ... AY42: =ROUND(SUM($BB29:$BY29)*AY$41,0) -> 180
C43: client B | D43: =ROUND(SUM($D30:$AA30)*D$41,0) -> 237 | E43: =ROUND(SUM($D30:$AA30)*E$41,0) -> 284 | F43: =ROUND(SUM($D30:$AA30)*F$41,0) -> 308 | G43: =ROUND(SUM($D30:$AA30)*G$41,0) -> 332 | H43: =ROUND(SUM($D30:$AA30)*H$41,0) -> 403 | I43: =ROUND(SUM($D30:$AA30)*I$41,0) -> 474 | J43: =ROUND(SUM($D30:$AA30)*J$41,0) -> 521 | K43: =ROUND(SUM($D30:$AA30)*K$41,0) -> 521 | ... O43: =ROUND(SUM($D30:$AA30)*O$41,0) -> 261 | P43: =ROUND(SUM($AC30:$AZ30)*P$41,0) -> 288 | Q43: =ROUND(SUM($AC30:$AZ30)*Q$41,0) -> 288 | R43: =ROUND(SUM($AC30:$AZ30)*R$41,0) -> 317 | S43: =ROUND(SUM($AC30:$AZ30)*S$41,0) -> 403 | T43: =ROUND(SUM($AC30:$AZ30)*T$41,0) -> 403 | U43: =ROUND(SUM($AC30:$AZ30)*U$41,0) -> 576 | V43: =ROUND(SUM($AC30:$AZ30)*V$41,0) -> 634 | W43: =ROUND(SUM($AC30:$AZ30)*W$41,0) -> 634 | ... AA43: =ROUND(SUM($AC30:$AZ30)*AA$41,0) -> 288 | AB43: =ROUND(SUM($BB30:$BY30)*AB$41,0) -> 294 | AC43: =ROUND(SUM($BB30:$BY30)*AC$41,0) -> 294 | AD43: =ROUND(SUM($BB30:$BY30)*AD$41,0) -> 294 | AE43: =ROUND(SUM($BB30:$BY30)*AE$41,0) -> 411 | AF43: =ROUND(SUM($BB30:$BY30)*AF$41,0) -> 411 | AG43: =ROUND(SUM($BB30:$BY30)*AG$41,0) -> 587 | AH43: =ROUND(SUM($BB30:$BY30)*AH$41,0) -> 646 | AI43: =ROUND(SUM($BB30:$BY30)*AI$41,0) -> 646 | ... AY43: =ROUND(SUM($BB30:$BY30)*AY$41,0) -> 294
C44: client C | D44: =ROUND(SUM($D31:$AA31)*D$41,0) -> 82 | E44: =ROUND(SUM($D31:$AA31)*E$41,0) -> 98 | F44: =ROUND(SUM($D31:$AA31)*F$41,0) -> 106 | G44: =ROUND(SUM($D31:$AA31)*G$41,0) -> 114 | H44: =ROUND(SUM($D31:$AA31)*H$41,0) -> 139 | I44: =ROUND(SUM($D31:$AA31)*I$41,0) -> 163 | J44: =ROUND(SUM($D31:$AA31)*J$41,0) -> 179 | K44: =ROUND(SUM($D31:$AA31)*K$41,0) -> 179 | ... O44: =ROUND(SUM($D31:$AA31)*O$41,0) -> 90 | P44: =ROUND(SUM($AC31:$AZ31)*P$41,0) -> 112 | Q44: =ROUND(SUM($AC31:$AZ31)*Q$41,0) -> 112 | R44: =ROUND(SUM($AC31:$AZ31)*R$41,0) -> 123 | S44: =ROUND(SUM($AC31:$AZ31)*S$41,0) -> 157 | T44: =ROUND(SUM($AC31:$AZ31)*T$41,0) -> 157 | U44: =ROUND(SUM($AC31:$AZ31)*U$41,0) -> 224 | V44: =ROUND(SUM($AC31:$AZ31)*V$41,0) -> 246 | W44: =ROUND(SUM($AC31:$AZ31)*W$41,0) -> 246 | ... AA44: =ROUND(SUM($AC31:$AZ31)*AA$41,0) -> 112 | AB44: =ROUND(SUM($BB31:$BY31)*AB$41,0) -> 93 | AC44: =ROUND(SUM($BB31:$BY31)*AC$41,0) -> 93 | AD44: =ROUND(SUM($BB31:$BY31)*AD$41,0) -> 93 | AE44: =ROUND(SUM($BB31:$BY31)*AE$41,0) -> 130 | AF44: =ROUND(SUM($BB31:$BY31)*AF$41,0) -> 130 | AG44: =ROUND(SUM($BB31:$BY31)*AG$41,0) -> 186 | AH44: =ROUND(SUM($BB31:$BY31)*AH$41,0) -> 205 | AI44: =ROUND(SUM($BB31:$BY31)*AI$41,0) -> 205 | ... AY44: =ROUND(SUM($BB31:$BY31)*AY$41,0) -> 93
C45: client D | D45: =ROUND(SUM($D32:$AA32)*D$41,0) -> 257 | E45: =ROUND(SUM($D32:$AA32)*E$41,0) -> 308 | F45: =ROUND(SUM($D32:$AA32)*F$41,0) -> 334 | G45: =ROUND(SUM($D32:$AA32)*G$41,0) -> 360 | H45: =ROUND(SUM($D32:$AA32)*H$41,0) -> 437 | I45: =ROUND(SUM($D32:$AA32)*I$41,0) -> 514 | J45: =ROUND(SUM($D32:$AA32)*J$41,0) -> 565 | K45: =ROUND(SUM($D32:$AA32)*K$41,0) -> 565 | ... O45: =ROUND(SUM($D32:$AA32)*O$41,0) -> 283 | P45: =ROUND(SUM($AC32:$AZ32)*P$41,0) -> 270 | Q45: =ROUND(SUM($AC32:$AZ32)*Q$41,0) -> 270 | R45: =ROUND(SUM($AC32:$AZ32)*R$41,0) -> 297 | S45: =ROUND(SUM($AC32:$AZ32)*S$41,0) -> 378 | T45: =ROUND(SUM($AC32:$AZ32)*T$41,0) -> 378 | U45: =ROUND(SUM($AC32:$AZ32)*U$41,0) -> 540 | V45: =ROUND(SUM($AC32:$AZ32)*V$41,0) -> 594 | W45: =ROUND(SUM($AC32:$AZ32)*W$41,0) -> 594 | ... AA45: =ROUND(SUM($AC32:$AZ32)*AA$41,0) -> 270 | AB45: =ROUND(SUM($BB32:$BY32)*AB$41,0) -> 285 | AC45: =ROUND(SUM($BB32:$BY32)*AC$41,0) -> 285 | AD45: =ROUND(SUM($BB32:$BY32)*AD$41,0) -> 285 | AE45: =ROUND(SUM($BB32:$BY32)*AE$41,0) -> 399 | AF45: =ROUND(SUM($BB32:$BY32)*AF$41,0) -> 399 | AG45: =ROUND(SUM($BB32:$BY32)*AG$41,0) -> 570 | AH45: =ROUND(SUM($BB32:$BY32)*AH$41,0) -> 627 | AI45: =ROUND(SUM($BB32:$BY32)*AI$41,0) -> 627 | ... AY45: =ROUND(SUM($BB32:$BY32)*AY$41,0) -> 285
C46: client E | D46: =ROUND(SUM($D33:$AA33)*D$41,0) -> 165 | E46: =ROUND(SUM($D33:$AA33)*E$41,0) -> 198 | F46: =ROUND(SUM($D33:$AA33)*F$41,0) -> 215 | G46: =ROUND(SUM($D33:$AA33)*G$41,0) -> 231 | H46: =ROUND(SUM($D33:$AA33)*H$41,0) -> 281 | I46: =ROUND(SUM($D33:$AA33)*I$41,0) -> 330 | J46: =ROUND(SUM($D33:$AA33)*J$41,0) -> 363 | K46: =ROUND(SUM($D33:$AA33)*K$41,0) -> 363 | ... O46: =ROUND(SUM($D33:$AA33)*O$41,0) -> 182 | P46: =ROUND(SUM($AC33:$AZ33)*P$41,0) -> 170 | Q46: =ROUND(SUM($AC33:$AZ33)*Q$41,0) -> 170 | R46: =ROUND(SUM($AC33:$AZ33)*R$41,0) -> 187 | S46: =ROUND(SUM($AC33:$AZ33)*S$41,0) -> 238 | T46: =ROUND(SUM($AC33:$AZ33)*T$41,0) -> 238 | U46: =ROUND(SUM($AC33:$AZ33)*U$41,0) -> 340 | V46: =ROUND(SUM($AC33:$AZ33)*V$41,0) -> 374 | W46: =ROUND(SUM($AC33:$AZ33)*W$41,0) -> 374 | ... AA46: =ROUND(SUM($AC33:$AZ33)*AA$41,0) -> 170 | AB46: =ROUND(SUM($BB33:$BY33)*AB$41,0) -> 180 | AC46: =ROUND(SUM($BB33:$BY33)*AC$41,0) -> 180 | AD46: =ROUND(SUM($BB33:$BY33)*AD$41,0) -> 180 | AE46: =ROUND(SUM($BB33:$BY33)*AE$41,0) -> 252 | AF46: =ROUND(SUM($BB33:$BY33)*AF$41,0) -> 252 | AG46: =ROUND(SUM($BB33:$BY33)*AG$41,0) -> 360 | AH46: =ROUND(SUM($BB33:$BY33)*AH$41,0) -> 396 | AI46: =ROUND(SUM($BB33:$BY33)*AI$41,0) -> 396 | ... AY46: =ROUND(SUM($BB33:$BY33)*AY$41,0) -> 180
D47: =ROUND(SUM($D34:$AA34)*D$41,0) -> 0 | E47: =ROUND(SUM($D34:$AA34)*E$41,0) -> 0 | F47: =ROUND(SUM($D34:$AA34)*F$41,0) -> 0 | G47: =ROUND(SUM($D34:$AA34)*G$41,0) -> 0 | H47: =ROUND(SUM($D34:$AA34)*H$41,0) -> 0 | I47: =ROUND(SUM($D34:$AA34)*I$41,0) -> 0 | J47: =ROUND(SUM($D34:$AA34)*J$41,0) -> 0 | K47: =ROUND(SUM($D34:$AA34)*K$41,0) -> 0 | ... O47: =ROUND(SUM($D34:$AA34)*O$41,0) -> 0 | P47: =ROUND(SUM($AC34:$AZ34)*P$41,0) -> 0 | Q47: =ROUND(SUM($AC34:$AZ34)*Q$41,0) -> 0 | R47: =ROUND(SUM($AC34:$AZ34)*R$41,0) -> 0 | S47: =ROUND(SUM($AC34:$AZ34)*S$41,0) -> 0 | T47: =ROUND(SUM($AC34:$AZ34)*T$41,0) -> 0 | U47: =ROUND(SUM($AC34:$AZ34)*U$41,0) -> 0 | V47: =ROUND(SUM($AC34:$AZ34)*V$41,0) -> 0 | W47: =ROUND(SUM($AC34:$AZ34)*W$41,0) -> 0 | ... AA47: =ROUND(SUM($AC34:$AZ34)*AA$41,0) -> 0 | AB47: =ROUND(SUM($BB34:$BY34)*AB$41,0) -> 0 | AC47: =ROUND(SUM($BB34:$BY34)*AC$41,0) -> 0 | AD47: =ROUND(SUM($BB34:$BY34)*AD$41,0) -> 0 | AE47: =ROUND(SUM($BB34:$BY34)*AE$41,0) -> 0 | AF47: =ROUND(SUM($BB34:$BY34)*AF$41,0) -> 0 | AG47: =ROUND(SUM($BB34:$BY34)*AG$41,0) -> 0 | AH47: =ROUND(SUM($BB34:$BY34)*AH$41,0) -> 0 | AI47: =ROUND(SUM($BB34:$BY34)*AI$41,0) -> 0 | ... AY47: =ROUND(SUM($BB34:$BY34)*AY$41,0) -> 0
C48: Nombre de client mensuel | D48: =SUM(D42:D47) -> 896 | E48: =SUM(E42:E47) -> 1073 | F48: =SUM(F42:F47) -> 1164 | G48: =SUM(G42:G47) -> 1253 | H48: =SUM(H42:H47) -> 1523 | I48: =SUM(I42:I47) -> 1790 | J48: =SUM(J42:J47) -> 1968 | K48: =SUM(K42:K47) -> 1968 | ... AY48: =SUM(AY42:AY47) -> 1032
...

Sheet Insights Livraison
A2: Restauration - Platefore de livraison
C3: Heure-Jour | D3: 2025 | K3: 2026 | R3: 2027
C4: % remplissage horaire | D4: 8h30-10h | E4: 10h-11h30 | F4: 11h30-13 | G4: 13h-14h30 | H4: 14h30-16h | I4: 16h-17h30 | K4: 8h30-10h | L4: 10h-11h30 | M4: 11h30-13 | N4: 13h-14h30 | O4: 14h30-16h | P4: 16h-17h30 | R4: 8h30-10h | S4: 10h-11h30 | T4: 11h30-13 | U4: 13h-14h30 | V4: 14h30-16h | W4: 16h-17h30
B5: 5.5 | C5: client A
B6: 10.1 | C6: client B | F6: 0.05 | H6: 0.3 | I6: 1 | M6: 0.05 | O6: 0.3 | P6: 1 | T6: 0.05 | V6: 0.3 | W6: 1
B7: 14 | C7: client C | F7: 0.05 | M7: 0.05 | T7: 0.05
B8: 18 | C8: client D | F8: 0.7 | G8: 0.8 | H8: 0.5 | M8: 0.7 | N8: 0.8 | O8: 0.5 | T8: 0.7 | U8: 0.8 | V8: 0.5
B9: 22.65 | C9: client E | F9: 0.2 | G9: 0.2 | H9: 0.2 | M9: 0.2 | N9: 0.2 | O9: 0.2 | T9: 0.2 | U9: 0.2 | V9: 0.2
D11: =SUM(D5:D10) -> 0 | E11: =SUM(E5:E10) -> 0 | F11: =SUM(F5:F10) -> 1 | G11: =SUM(G5:G10) -> 1 | H11: =SUM(H5:H10) -> 1 | I11: =SUM(I5:I10) -> 1 | K11: =SUM(K5:K10) -> 0 | L11: =SUM(L5:L10) -> 0 | M11: =SUM(M5:M10) -> 1 | N11: =SUM(N5:N10) -> 1 | O11: =SUM(O5:O10) -> 1 | P11: =SUM(P5:P10) -> 1 | R11: =SUM(R5:R10) -> 0 | S11: =SUM(S5:S10) -> 0 | T11: =SUM(T5:T10) -> 1 | U11: =SUM(U5:U10) -> 1 | V11: =SUM(V5:V10) -> 1 | W11: =SUM(W5:W10) -> 1
C14: Heure-Jour | D14: 2025 | K14: 2026 | R14: 2027
D15: 8h30-10h | E15: 10h-11h30 | F15: 11h30-13 | G15: 13h-14h30 | H15: 14h30-16h | I15: 16h-17h30 | K15: 8h30-10h | L15: 10h-11h30 | M15: 11h30-13 | N15: 13h-14h30 | O15: 14h30-16h | P15: 16h-17h30 | R15: 8h30-10h | S15: 10h-11h30 | T15: 11h30-13 | U15: 13h-14h30 | V15: 14h30-16h | W15: 16h-17h30
C16: Nombre de clients | F16: 10 | G16: 9 | H16: 9 | I16: 5 | M16: 12 | N16: 12 | O16: 10 | P16: 5 | T16: 13 | U16: 12 | V16: 10 | W16: 5
C17: client A | D17: =ROUND( D$16*D5,0) -> 0 | E17: =ROUND( E$16*E5,0) -> 0 | F17: =ROUND( F$16*F5,0) -> 0 | G17: =ROUND( G$16*G5,0) -> 0 | H17: =ROUND( H$16*H5,0) -> 0 | I17: =ROUND( I$16*I5,0) -> 0 | K17: =ROUND( K$16*K5,0) -> 0 | L17: =ROUND( L$16*L5,0) -> 0 | M17: =ROUND( M$16*M5,0) -> 0 | N17: =ROUND( N$16*N5,0) -> 0 | O17: =ROUND( O$16*O5,0) -> 0 | P17: =ROUND( P$16*P5,0) -> 0 | R17: =ROUND( R$16*R5,0) -> 0 | S17: =ROUND( S$16*S5,0) -> 0 | T17: =ROUND( T$16*T5,0) -> 0 | U17: =ROUND( U$16*U5,0) -> 0 | V17: =ROUND( V$16*V5,0) -> 0 | W17: =ROUND( W$16*W5,0) -> 0
C18: client B | D18: =ROUND( D$16*D6,0) -> 0 | E18: =ROUND( E$16*E6,0) -> 0 | F18: =ROUND( F$16*F6,0) -> 1 | G18: =ROUND( G$16*G6,0) -> 0 | H18: =ROUND( H$16*H6,0) -> 3 | I18: =ROUND( I$16*I6,0) -> 5 | K18: =ROUND( K$16*K6,0) -> 0 | L18: =ROUND( L$16*L6,0) -> 0 | M18: =ROUND( M$16*M6,0) -> 1 | N18: =ROUND( N$16*N6,0) -> 0 | O18: =ROUND( O$16*O6,0) -> 3 | P18: =ROUND( P$16*P6,0) -> 5 | R18: =ROUND( R$16*R6,0) -> 0 | S18: =ROUND( S$16*S6,0) -> 0 | T18: =ROUND( T$16*T6,0) -> 1 | U18: =ROUND( U$16*U6,0) -> 0 | V18: =ROUND( V$16*V6,0) -> 3 | W18: =ROUND( W$16*W6,0) -> 5
C19: client C | D19: =ROUND( D$16*D7,0) -> 0 | E19: =ROUND( E$16*E7,0) -> 0 | F19: =ROUND( F$16*F7,0) -> 1 | G19: =ROUND( G$16*G7,0) -> 0 | H19: =ROUND( H$16*H7,0) -> 0 | I19: =ROUND( I$16*I7,0) -> 0 | K19: =ROUND( K$16*K7,0) -> 0 | L19: =ROUND( L$16*L7,0) -> 0 | M19: =ROUND( M$16*M7,0) -> 1 | N19: =ROUND( N$16*N7,0) -> 0 | O19: =ROUND( O$16*O7,0) -> 0 | P19: =ROUND( P$16*P7,0) -> 0 | R19: =ROUND( R$16*R7,0) -> 0 | S19: =ROUND( S$16*S7,0) -> 0 | T19: =ROUND( T$16*T7,0) -> 1 | U19: =ROUND( U$16*U7,0) -> 0 | V19: =ROUND( V$16*V7,0) -> 0 | W19: =ROUND( W$16*W7,0) -> 0
C20: client D | D20: =ROUND( D$16*D8,0) -> 0 | E20: =ROUND( E$16*E8,0) -> 0 | F20: =ROUND( F$16*F8,0) -> 7 | G20: =ROUND( G$16*G8,0) -> 7 | H20: =ROUND( H$16*H8,0) -> 5 | I20: =ROUND( I$16*I8,0) -> 0 | K20: =ROUND( K$16*K8,0) -> 0 | L20: =ROUND( L$16*L8,0) -> 0 | M20: =ROUND( M$16*M8,0) -> 8 | N20: =ROUND( N$16*N8,0) -> 10 | O20: =ROUND( O$16*O8,0) -> 5 | P20: =ROUND( P$16*P8,0) -> 0 | R20: =ROUND( R$16*R8,0) -> 0 | S20: =ROUND( S$16*S8,0) -> 0 | T20: =ROUND( T$16*T8,0) -> 9 | U20: =ROUND( U$16*U8,0) -> 10 | V20: =ROUND( V$16*V8,0) -> 5 | W20: =ROUND( W$16*W8,0) -> 0
C21: client E | D21: =ROUND( D$16*D9,0) -> 0 | E21: =ROUND( E$16*E9,0) -> 0 | F21: =ROUND( F$16*F9,0) -> 2 | G21: =ROUND( G$16*G9,0) -> 2 | H21: =ROUND( H$16*H9,0) -> 2 | I21: =ROUND( I$16*I9,0) -> 0 | K21: =ROUND( K$16*K9,0) -> 0 | L21: =ROUND( L$16*L9,0) -> 0 | M21: =ROUND( M$16*M9,0) -> 2 | N21: =ROUND( N$16*N9,0) -> 2 | O21: =ROUND( O$16*O9,0) -> 2 | P21: =ROUND( P$16*P9,0) -> 0 | R21: =ROUND( R$16*R9,0) -> 0 | S21: =ROUND( S$16*S9,0) -> 0 | T21: =ROUND( T$16*T9,0) -> 3 | U21: =ROUND( U$16*U9,0) -> 2 | V21: =ROUND( V$16*V9,0) -> 2 | W21: =ROUND( W$16*W9,0) -> 0
D22: =ROUND( D$16*D10,0) -> 0 | E22: =ROUND( E$16*E10,0) -> 0 | F22: =ROUND( F$16*F10,0) -> 0 | G22: =ROUND( G$16*G10,0) -> 0 | H22: =ROUND( H$16*H10,0) -> 0 | I22: =ROUND( I$16*I10,0) -> 0 | K22: =ROUND( K$16*K10,0) -> 0 | L22: =ROUND( L$16*L10,0) -> 0 | M22: =ROUND( M$16*M10,0) -> 0 | N22: =ROUND( N$16*N10,0) -> 0 | O22: =ROUND( O$16*O10,0) -> 0 | P22: =ROUND( P$16*P10,0) -> 0 | R22: =ROUND( R$16*R10,0) -> 0 | S22: =ROUND( S$16*S10,0) -> 0 | T22: =ROUND( T$16*T10,0) -> 0 | U22: =ROUND( U$16*U10,0) -> 0 | V22: =ROUND( V$16*V10,0) -> 0 | W22: =ROUND( W$16*W10,0) -> 0
D23: =SUM(D17:D22) -> 0 | E23: =SUM(E17:E22) -> 0 | F23: =SUM(F17:F22) -> 11 | G23: =SUM(G17:G22) -> 9 | H23: =SUM(H17:H22) -> 10 | I23: =SUM(I17:I22) -> 5 | K23: =SUM(K17:K22) -> 0 | L23: =SUM(L17:L22) -> 0 | M23: =SUM(M17:M22) -> 12 | N23: =SUM(N17:N22) -> 12 | O23: =SUM(O17:O22) -> 10 | P23: =SUM(P17:P22) -> 5 | R23: =SUM(R17:R22) -> 0 | S23: =SUM(S17:S22) -> 0 | T23: =SUM(T17:T22) -> 14 | U23: =SUM(U17:U22) -> 12 | V23: =SUM(V17:V22) -> 10 | W23: =SUM(W17:W22) -> 5
D25: 2025 | AC25: 2026 | BB25: 2027
C26: jour/mois | D26: mardi | E26: mercredi | F26: jeudi | G26: vendredi | H26: samedi | I26: dimanche | J26: mardi | K26: mercredi | L26: jeudi | M26: vendredi | N26: samedi | O26: dimanche | P26: mardi | Q26: mercredi | R26: jeudi | S26: vendredi | T26: samedi | U26: dimanche | V26: mardi | W26: mercredi | X26: jeudi | Y26: vendredi | Z26: samedi | AA26: dimanche | AC26: mardi | AD26: mercredi | AE26: jeudi | AF26: vendredi | AG26: samedi | AH26: dimanche | AI26: mardi | AJ26: mercredi | AK26: jeudi | AL26: vendredi | AM26: samedi | AN26: dimanche | AO26: mardi | AP26: mercredi | AQ26: jeudi | AR26: vendredi | AS26: samedi | AT26: dimanche | AU26: mardi | AV26: mercredi | AW26: jeudi | AX26: vendredi | AY26: samedi | AZ26: dimanche | BB26: mardi | BC26: mercredi | BD26: jeudi | BE26: vendredi | BF26: samedi | BG26: dimanche | BH26: mardi | BI26: mercredi | BJ26: jeudi | BK26: vendredi | BL26: samedi | BM26: dimanche | BN26: mardi | BO26: mercredi | BP26: jeudi | BQ26: vendredi | BR26: samedi | BS26: dimanche | BT26: mardi | BU26: mercredi | BV26: jeudi | BW26: vendredi | BX26: samedi | BY26: dimanche
D27: 1 | E27: 2 | F27: 3 | G27: 4 | H27: 5 | I27: 6 | J27: 7 | K27: 8 | L27: 9 | M27: 10 | N27: 11 | O27: 12 | P27: 13 | Q27: 14 | R27: 15 | S27: 16 | T27: 17 | U27: 18 | V27: 19 | W27: 20 | X27: 21 | Y27: 22 | Z27: 23 | AA27: 24 | AC27: 1 | AD27: 2 | AE27: 3 | AF27: 4 | AG27: 5 | AH27: 6 | AI27: 7 | AJ27: 8 | AK27: 9 | AL27: 10 | AM27: 11 | AN27: 12 | AO27: 13 | AP27: 14 | AQ27: 15 | AR27: 16 | AS27: 17 | AT27: 18 | AU27: 19 | AV27: 20 | AW27: 21 | AX27: 22 | AY27: 23 | AZ27: 24 | BB27: 1 | BC27: 2 | BD27: 3 | BE27: 4 | BF27: 5 | BG27: 6 | BH27: 7 | BI27: 8 | BJ27: 9 | BK27: 10 | BL27: 11 | BM27: 12 | BN27: 13 | BO27: 14 | BP27: 15 | BQ27: 16 | BR27: 17 | BS27: 18 | BT27: 19 | BU27: 20 | BV27: 21 | BW27: 22 | BX27: 23 | BY27: 24
C28: % remplissage journalier | D28: 0.5 | E28: 0.5 | F28: 0.7 | G28: 0.7 | H28: 0.7 | I28: 0.7 | J28: 0.5 | K28: 0.5 | L28: 0.7 | M28: 0.7 | N28: 0.7 | O28: 0.7 | P28: 0.5 | Q28: 0.5 | R28: 0.7 | S28: 0.7 | T28: 0.7 | U28: 0.7 | V28: 0.5 | W28: 0.5 | X28: 0.7 | Y28: 0.7 | Z28: 0.7 | AA28: 0.7 | AC28: 0.4 | AD28: 0.4 | AE28: 0.4 | AF28: 0.5 | AG28: 0.5 | AH28: 0.5 | AI28: 0.4 | AJ28: 0.4 | AK28: 0.4 | AL28: 0.5 | AM28: 0.5 | AN28: 0.5 | AO28: 0.4 | AP28: 0.4 | AQ28: 0.4 | AR28: 0.5 | AS28: 0.5 | AT28: 0.5 | AU28: 0.4 | AV28: 0.4 | AW28: 0.4 | AX28: 0.5 | AY28: 0.5 | AZ28: 0.5 | BB28: 0.4 | BC28: 0.4 | BD28: 0.5 | BE28: 0.5 | BF28: 0.5 | BG28: 0.5 | BH28: 0.4 | BI28: 0.4 | BJ28: 0.4 | BK28: 0.5 | BL28: 0.5 | BM28: 0.5 | BN28: 0.4 | BO28: 0.4 | BP28: 0.4 | BQ28: 0.5 | BR28: 0.5 | BS28: 0.5 | BT28: 0.4 | BU28: 0.4 | BV28: 0.4 | BW28: 0.5 | BX28: 0.5 | BY28: 0.5
C29: client A | D29: =ROUND(SUM($D17:$I17)*D$28,0) -> 0 | E29: =ROUND(SUM($D17:$I17)*E$28,0) -> 0 | F29: =ROUND(SUM($D17:$I17)*F$28,0) -> 0 | G29: =ROUND(SUM($D17:$I17)*G$28,0) -> 0 | H29: =ROUND(SUM($D17:$I17)*H$28,0) -> 0 | I29: =ROUND(SUM($D17:$I17)*I$28,0) -> 0 | J29: =ROUND(SUM($D17:$I17)*J$28,0) -> 0 | K29: =ROUND(SUM($D17:$I17)*K$28,0) -> 0 | ... AA29: =ROUND(SUM($D17:$I17)*AA$28,0) -> 0 | AC29: =ROUND(SUM($K17:$P17)*AC$28,0) -> 0 | AD29: =ROUND(SUM($K17:$P17)*AD$28,0) -> 0 | AE29: =ROUND(SUM($K17:$P17)*AE$28,0) -> 0 | AF29: =ROUND(SUM($K17:$P17)*AF$28,0) -> 0 | AG29: =ROUND(SUM($K17:$P17)*AG$28,0) -> 0 | AH29: =ROUND(SUM($K17:$P17)*AH$28,0) -> 0 | AI29: =ROUND(SUM($K17:$P17)*AI$28,0) -> 0 | AJ29: =ROUND(SUM($K17:$P17)*AJ$28,0) -> 0 | ... AZ29: =ROUND(SUM($K17:$P17)*AZ$28,0) -> 0 | BB29: =ROUND(SUM($R17:$W17)*BB$28,0) -> 0 | BC29: =ROUND(SUM($R17:$W17)*BC$28,0) -> 0 | BD29: =ROUND(SUM($R17:$W17)*BD$28,0) -> 0 | BE29: =ROUND(SUM($R17:$W17)*BE$28,0) -> 0 | BF29: =ROUND(SUM($R17:$W17)*BF$28,0) -> 0 | BG29: =ROUND(SUM($R17:$W17)*BG$28,0) -> 0 | BH29: =ROUND(SUM($R17:$W17)*BH$28,0) -> 0 | BI29: =ROUND(SUM($R17:$W17)*BI$28,0) -> 0 | ... BY29: =ROUND(SUM($R17:$W17)*BY$28,0) -> 0
C30: client B | D30: =ROUND(SUM($D18:$I18)*D$28,0) -> 5 | E30: =ROUND(SUM($D18:$I18)*E$28,0) -> 5 | F30: =ROUND(SUM($D18:$I18)*F$28,0) -> 6 | G30: =ROUND(SUM($D18:$I18)*G$28,0) -> 6 | H30: =ROUND(SUM($D18:$I18)*H$28,0) -> 6 | I30: =ROUND(SUM($D18:$I18)*I$28,0) -> 6 | J30: =ROUND(SUM($D18:$I18)*J$28,0) -> 5 | K30: =ROUND(SUM($D18:$I18)*K$28,0) -> 5 | ... AA30: =ROUND(SUM($D18:$I18)*AA$28,0) -> 6 | AC30: =ROUND(SUM($K18:$P18)*AC$28,0) -> 4 | AD30: =ROUND(SUM($K18:$P18)*AD$28,0) -> 4 | AE30: =ROUND(SUM($K18:$P18)*AE$28,0) -> 4 | AF30: =ROUND(SUM($K18:$P18)*AF$28,0) -> 5 | AG30: =ROUND(SUM($K18:$P18)*AG$28,0) -> 5 | AH30: =ROUND(SUM($K18:$P18)*AH$28,0) -> 5 | AI30: =ROUND(SUM($K18:$P18)*AI$28,0) -> 4 | AJ30: =ROUND(SUM($K18:$P18)*AJ$28,0) -> 4 | ... AZ30: =ROUND(SUM($K18:$P18)*AZ$28,0) -> 5 | BB30: =ROUND(SUM($R18:$W18)*BB$28,0) -> 4 | BC30: =ROUND(SUM($R18:$W18)*BC$28,0) -> 4 | BD30: =ROUND(SUM($R18:$W18)*BD$28,0) -> 5 | BE30: =ROUND(SUM($R18:$W18)*BE$28,0) -> 5 | BF30: =ROUND(SUM($R18:$W18)*BF$28,0) -> 5 | BG30: =ROUND(SUM($R18:$W18)*BG$28,0) -> 5 | BH30: =ROUND(SUM($R18:$W18)*BH$28,0) -> 4 | BI30: =ROUND(SUM($R18:$W18)*BI$28,0) -> 4 | ... BY30: =ROUND(SUM($R18:$W18)*BY$28,0) -> 5
C31: client C | D31: =ROUND(SUM($D19:$I19)*D$28,0) -> 1 | E31: =ROUND(SUM($D19:$I19)*E$28,0) -> 1 | F31: =ROUND(SUM($D19:$I19)*F$28,0) -> 1 | G31: =ROUND(SUM($D19:$I19)*G$28,0) -> 1 | H31: =ROUND(SUM($D19:$I19)*H$28,0) -> 1 | I31: =ROUND(SUM($D19:$I19)*I$28,0) -> 1 | J31: =ROUND(SUM($D19:$I19)*J$28,0) -> 1 | K31: =ROUND(SUM($D19:$I19)*K$28,0) -> 1 | ... AA31: =ROUND(SUM($D19:$I19)*AA$28,0) -> 1 | AC31: =ROUND(SUM($K19:$P19)*AC$28,0) -> 0 | AD31: =ROUND(SUM($K19:$P19)*AD$28,0) -> 0 | AE31: =ROUND(SUM($K19:$P19)*AE$28,0) -> 0 | AF31: =ROUND(SUM($K19:$P19)*AF$28,0) -> 1 | AG31: =ROUND(SUM($K19:$P19)*AG$28,0) -> 1 | AH31: =ROUND(SUM($K19:$P19)*AH$28,0) -> 1 | AI31: =ROUND(SUM($K19:$P19)*AI$28,0) -> 0 | AJ31: =ROUND(SUM($K19:$P19)*AJ$28,0) -> 0 | ... AZ31: =ROUND(SUM($K19:$P19)*AZ$28,0) -> 1 | BB31: =ROUND(SUM($R19:$W19)*BB$28,0) -> 0 | BC31: =ROUND(SUM($R19:$W19)*BC$28,0) -> 0 | BD31: =ROUND(SUM($R19:$W19)*BD$28,0) -> 1 | BE31: =ROUND(SUM($R19:$W19)*BE$28,0) -> 1 | BF31: =ROUND(SUM($R19:$W19)*BF$28,0) -> 1 | BG31: =ROUND(SUM($R19:$W19)*BG$28,0) -> 1 | BH31: =ROUND(SUM($R19:$W19)*BH$28,0) -> 0 | BI31: =ROUND(SUM($R19:$W19)*BI$28,0) -> 0 | ... BY31: =ROUND(SUM($R19:$W19)*BY$28,0) -> 1
C32: client D | D32: =ROUND(SUM($D20:$I20)*D$28,0) -> 10 | E32: =ROUND(SUM($D20:$I20)*E$28,0) -> 10 | F32: =ROUND(SUM($D20:$I20)*F$28,0) -> 13 | G32: =ROUND(SUM($D20:$I20)*G$28,0) -> 13 | H32: =ROUND(SUM($D20:$I20)*H$28,0) -> 13 | I32: =ROUND(SUM($D20:$I20)*I$28,0) -> 13 | J32: =ROUND(SUM($D20:$I20)*J$28,0) -> 10 | K32: =ROUND(SUM($D20:$I20)*K$28,0) -> 10 | ... AA32: =ROUND(SUM($D20:$I20)*AA$28,0) -> 13 | AC32: =ROUND(SUM($K20:$P20)*AC$28,0) -> 9 | AD32: =ROUND(SUM($K20:$P20)*AD$28,0) -> 9 | AE32: =ROUND(SUM($K20:$P20)*AE$28,0) -> 9 | AF32: =ROUND(SUM($K20:$P20)*AF$28,0) -> 12 | AG32: =ROUND(SUM($K20:$P20)*AG$28,0) -> 12 | AH32: =ROUND(SUM($K20:$P20)*AH$28,0) -> 12 | AI32: =ROUND(SUM($K20:$P20)*AI$28,0) -> 9 | AJ32: =ROUND(SUM($K20:$P20)*AJ$28,0) -> 9 | ... AZ32: =ROUND(SUM($K20:$P20)*AZ$28,0) -> 12 | BB32: =ROUND(SUM($R20:$W20)*BB$28,0) -> 10 | BC32: =ROUND(SUM($R20:$W20)*BC$28,0) -> 10 | BD32: =ROUND(SUM($R20:$W20)*BD$28,0) -> 12 | BE32: =ROUND(SUM($R20:$W20)*BE$28,0) -> 12 | BF32: =ROUND(SUM($R20:$W20)*BF$28,0) -> 12 | BG32: =ROUND(SUM($R20:$W20)*BG$28,0) -> 12 | BH32: =ROUND(SUM($R20:$W20)*BH$28,0) -> 10 | BI32: =ROUND(SUM($R20:$W20)*BI$28,0) -> 10 | ... BY32: =ROUND(SUM($R20:$W20)*BY$28,0) -> 12
C33: client E | D33: =ROUND(SUM($D21:$I21)*D$28,0) -> 3 | E33: =ROUND(SUM($D21:$I21)*E$28,0) -> 3 | F33: =ROUND(SUM($D21:$I21)*F$28,0) -> 4 | G33: =ROUND(SUM($D21:$I21)*G$28,0) -> 4 | H33: =ROUND(SUM($D21:$I21)*H$28,0) -> 4 | I33: =ROUND(SUM($D21:$I21)*I$28,0) -> 4 | J33: =ROUND(SUM($D21:$I21)*J$28,0) -> 3 | K33: =ROUND(SUM($D21:$I21)*K$28,0) -> 3 | ... AA33: =ROUND(SUM($D21:$I21)*AA$28,0) -> 4 | AC33: =ROUND(SUM($K21:$P21)*AC$28,0) -> 2 | AD33: =ROUND(SUM($K21:$P21)*AD$28,0) -> 2 | AE33: =ROUND(SUM($K21:$P21)*AE$28,0) -> 2 | AF33: =ROUND(SUM($K21:$P21)*AF$28,0) -> 3 | AG33: =ROUND(SUM($K21:$P21)*AG$28,0) -> 3 | AH33: =ROUND(SUM($K21:$P21)*AH$28,0) -> 3 | AI33: =ROUND(SUM($K21:$P21)*AI$28,0) -> 2 | AJ33: =ROUND(SUM($K21:$P21)*AJ$28,0) -> 2 | ... AZ33: =ROUND(SUM($K21:$P21)*AZ$28,0) -> 3 | BB33: =ROUND(SUM($R21:$W21)*BB$28,0) -> 3 | BC33: =ROUND(SUM($R21:$W21)*BC$28,0) -> 3 | BD33: =ROUND(SUM($R21:$W21)*BD$28,0) -> 4 | BE33: =ROUND(SUM($R21:$W21)*BE$28,0) -> 4 | BF33: =ROUND(SUM($R21:$W21)*BF$28,0) -> 4 | BG33: =ROUND(SUM($R21:$W21)*BG$28,0) -> 4 | BH33: =ROUND(SUM($R21:$W21)*BH$28,0) -> 3 | BI33: =ROUND(SUM($R21:$W21)*BI$28,0) -> 3 | ... BY33: =ROUND(SUM($R21:$W21)*BY$28,0) -> 4
D34: =ROUND(SUM($D22:$I22)*D$28,0) -> 0 | E34: =ROUND(SUM($D22:$I22)*E$28,0) -> 0 | F34: =ROUND(SUM($D22:$I22)*F$28,0) -> 0 | G34: =ROUND(SUM($D22:$I22)*G$28,0) -> 0 | H34: =ROUND(SUM($D22:$I22)*H$28,0) -> 0 | I34: =ROUND(SUM($D22:$I22)*I$28,0) -> 0 | J34: =ROUND(SUM($D22:$I22)*J$28,0) -> 0 | K34: =ROUND(SUM($D22:$I22)*K$28,0) -> 0 | ... AA34: =ROUND(SUM($D22:$I22)*AA$28,0) -> 0 | AC34: =ROUND(SUM($K22:$P22)*AC$28,0) -> 0 | AD34: =ROUND(SUM($K22:$P22)*AD$28,0) -> 0 | AE34: =ROUND(SUM($K22:$P22)*AE$28,0) -> 0 | AF34: =ROUND(SUM($K22:$P22)*AF$28,0) -> 0 | AG34: =ROUND(SUM($K22:$P22)*AG$28,0) -> 0 | AH34: =ROUND(SUM($K22:$P22)*AH$28,0) -> 0 | AI34: =ROUND(SUM($K22:$P22)*AI$28,0) -> 0 | AJ34: =ROUND(SUM($K22:$P22)*AJ$28,0) -> 0 | ... AZ34: =ROUND(SUM($K22:$P22)*AZ$28,0) -> 0 | BB34: =ROUND(SUM($R22:$W22)*BB$28,0) -> 0 | BC34: =ROUND(SUM($R22:$W22)*BC$28,0) -> 0 | BD34: =ROUND(SUM($R22:$W22)*BD$28,0) -> 0 | BE34: =ROUND(SUM($R22:$W22)*BE$28,0) -> 0 | BF34: =ROUND(SUM($R22:$W22)*BF$28,0) -> 0 | BG34: =ROUND(SUM($R22:$W22)*BG$28,0) -> 0 | BH34: =ROUND(SUM($R22:$W22)*BH$28,0) -> 0 | BI34: =ROUND(SUM($R22:$W22)*BI$28,0) -> 0 | ... BY34: =ROUND(SUM($R22:$W22)*BY$28,0) -> 0
D35: =SUM(D29:D34) -> 19 | E35: =SUM(E29:E34) -> 19 | F35: =SUM(F29:F34) -> 24 | G35: =SUM(G29:G34) -> 24 | H35: =SUM(H29:H34) -> 24 | I35: =SUM(I29:I34) -> 24 | J35: =SUM(J29:J34) -> 19 | K35: =SUM(K29:K34) -> 19 | ... AA35: =SUM(AA29:AA34) -> 24 | AC35: =SUM(AC29:AC34) -> 15 | AD35: =SUM(AD29:AD34) -> 15 | AE35: =SUM(AE29:AE34) -> 15 | AF35: =SUM(AF29:AF34) -> 21 | AG35: =SUM(AG29:AG34) -> 21 | AH35: =SUM(AH29:AH34) -> 21 | AI35: =SUM(AI29:AI34) -> 15 | AJ35: =SUM(AJ29:AJ34) -> 15 | ... AZ35: =SUM(AZ29:AZ34) -> 21 | BB35: =SUM(BB29:BB34) -> 17 | BC35: =SUM(BC29:BC34) -> 17 | BD35: =SUM(BD29:BD34) -> 22 | BE35: =SUM(BE29:BE34) -> 22 | BF35: =SUM(BF29:BF34) -> 22 | BG35: =SUM(BG29:BG34) -> 22 | BH35: =SUM(BH29:BH34) -> 17 | BI35: =SUM(BI29:BI34) -> 17 | ... BY35: =SUM(BY29:BY34) -> 22
C38: Evolution des mois
D39: 2025 | P39: 2026 | AB39: 2027 | AN39: 2028
C40: Mois | D40: 1 | E40: 2 | F40: 3 | G40: 4 | H40: 5 | I40: 6 | J40: 7 | K40: 8 | L40: 9 | M40: 10 | N40: 11 | O40: 12 | P40: 1 | Q40: 2 | R40: 3 | S40: 4 | T40: 5 | U40: 6 | V40: 7 | W40: 8 | X40: 9 | Y40: 10 | Z40: 11 | AA40: 12 | AB40: 1 | AC40: 2 | AD40: 3 | AE40: 4 | AF40: 5 | AG40: 6 | AH40: 7 | AI40: 8 | AJ40: 9 | AK40: 10 | AL40: 11 | AM40: 12 | AN40: 1 | AO40: 2 | AP40: 3 | AQ40: 4 | AR40: 5 | AS40: 6 | AT40: 7 | AU40: 8 | AV40: 9 | AW40: 10 | AX40: 11 | AY40: 12
C41: % remplissage mensuel | D41: 0 | E41: 0 | F41: 0 | G41: 0.4 | H41: 0.6 | I41: 0.6 | J41: 0.7 | K41: 0.7 | L41: 0.7 | M41: 0.7 | N41: 0.5 | O41: 0.3 | P41: 0.5 | Q41: 0.5 | R41: 0.5 | S41: 0.5 | T41: 0.6 | U41: 0.6 | V41: 0.6 | W41: 0.6 | X41: 0.7 | Y41: 0.5 | Z41: 0.6 | AA41: 0.5 | AB41: 0.4 | AC41: 0.4 | AD41: 0.4 | AE41: 0.5 | AF41: 0.6 | AG41: 0.6 | AH41: 0.6 | AI41: 0.6 | AJ41: 0.7 | AK41: 0.5 | AL41: 0.6 | AM41: 0.5 | AN41: 0.6 | AO41: 0.6 | AP41: 0.6 | AQ41: 0.6 | AR41: 0.6 | AS41: 0.6 | AT41: 0.6 | AU41: 0.7 | AV41: 0.7 | AW41: 0.5 | AX41: 0.3 | AY41: 0.3
C42: client A | D42: =ROUND(SUM($D29:$AA29)*D$41,0) -> 0 | E42: =ROUND(SUM($D29:$AA29)*E$41,0) -> 0 | F42: =ROUND(SUM($D29:$AA29)*F$41,0) -> 0 | G42: =ROUND(SUM($D29:$AA29)*G$41,0) -> 0 | H42: =ROUND(SUM($D29:$AA29)*H$41,0) -> 0 | I42: =ROUND(SUM($D29:$AA29)*I$41,0) -> 0 | J42: =ROUND(SUM($D29:$AA29)*J$41,0) -> 0 | K42: =ROUND(SUM($D29:$AA29)*K$41,0) -> 0 | ... O42: =ROUND(SUM($D29:$AA29)*O$41,0) -> 0 | P42: =ROUND(SUM($AC29:$AZ29)*P$41,0) -> 0 | Q42: =ROUND(SUM($AC29:$AZ29)*Q$41,0) -> 0 | R42: =ROUND(SUM($AC29:$AZ29)*R$41,0) -> 0 | S42: =ROUND(SUM($AC29:$AZ29)*S$41,0) -> 0 | T42: =ROUND(SUM($AC29:$AZ29)*T$41,0) -> 0 | U42: =ROUND(SUM($AC29:$AZ29)*U$41,0) -> 0 | V42: =ROUND(SUM($AC29:$AZ29)*V$41,0) -> 0 | W42: =ROUND(SUM($AC29:$AZ29)*W$41,0) -> 0 | ... AA42: =ROUND(SUM($AC29:$AZ29)*AA$41,0) -> 0 | AB42: =ROUND(SUM($BB29:$BY29)*AB$41,0) -> 0 | AC42: =ROUND(SUM($BB29:$BY29)*AC$41,0) -> 0 | AD42: =ROUND(SUM($BB29:$BY29)*AD$41,0) -> 0 | AE42: =ROUND(SUM($BB29:$BY29)*AE$41,0) -> 0 | AF42: =ROUND(SUM($BB29:$BY29)*AF$41,0) -> 0 | AG42: =ROUND(SUM($BB29:$BY29)*AG$41,0) -> 0 | AH42: =ROUND(SUM($BB29:$BY29)*AH$41,0) -> 0 | AI42: =ROUND(SUM($BB29:$BY29)*AI$41,0) -> 0 | ... AY42: =ROUND(SUM($BB29:$BY29)*AY$41,0) -> 0
C43: client B | D43: =ROUND(SUM($D30:$AA30)*D$41,0) -> 0 | E43: =ROUND(SUM($D30:$AA30)*E$41,0) -> 0 | F43: =ROUND(SUM($D30:$AA30)*F$41,0) -> 0 | G43: =ROUND(SUM($D30:$AA30)*G$41,0) -> 54 | H43: =ROUND(SUM($D30:$AA30)*H$41,0) -> 82 | I43: =ROUND(SUM($D30:$AA30)*I$41,0) -> 82 | J43: =ROUND(SUM($D30:$AA30)*J$41,0) -> 95 | K43: =ROUND(SUM($D30:$AA30)*K$41,0) -> 95 | ... O43: =ROUND(SUM($D30:$AA30)*O$41,0) -> 41 | P43: =ROUND(SUM($AC30:$AZ30)*P$41,0) -> 54 | Q43: =ROUND(SUM($AC30:$AZ30)*Q$41,0) -> 54 | R43: =ROUND(SUM($AC30:$AZ30)*R$41,0) -> 54 | S43: =ROUND(SUM($AC30:$AZ30)*S$41,0) -> 54 | T43: =ROUND(SUM($AC30:$AZ30)*T$41,0) -> 65 | U43: =ROUND(SUM($AC30:$AZ30)*U$41,0) -> 65 | V43: =ROUND(SUM($AC30:$AZ30)*V$41,0) -> 65 | W43: =ROUND(SUM($AC30:$AZ30)*W$41,0) -> 65 | ... AA43: =ROUND(SUM($AC30:$AZ30)*AA$41,0) -> 54 | AB43: =ROUND(SUM($BB30:$BY30)*AB$41,0) -> 44 | AC43: =ROUND(SUM($BB30:$BY30)*AC$41,0) -> 44 | AD43: =ROUND(SUM($BB30:$BY30)*AD$41,0) -> 44 | AE43: =ROUND(SUM($BB30:$BY30)*AE$41,0) -> 55 | AF43: =ROUND(SUM($BB30:$BY30)*AF$41,0) -> 65 | AG43: =ROUND(SUM($BB30:$BY30)*AG$41,0) -> 65 | AH43: =ROUND(SUM($BB30:$BY30)*AH$41,0) -> 65 | AI43: =ROUND(SUM($BB30:$BY30)*AI$41,0) -> 65 | ... AY43: =ROUND(SUM($BB30:$BY30)*AY$41,0) -> 33
C44: client C | D44: =ROUND(SUM($D31:$AA31)*D$41,0) -> 0 | E44: =ROUND(SUM($D31:$AA31)*E$41,0) -> 0 | F44: =ROUND(SUM($D31:$AA31)*F$41,0) -> 0 | G44: =ROUND(SUM($D31:$AA31)*G$41,0) -> 10 | H44: =ROUND(SUM($D31:$AA31)*H$41,0) -> 14 | I44: =ROUND(SUM($D31:$AA31)*I$41,0) -> 14 | J44: =ROUND(SUM($D31:$AA31)*J$41,0) -> 17 | K44: =ROUND(SUM($D31:$AA31)*K$41,0) -> 17 | ... O44: =ROUND(SUM($D31:$AA31)*O$41,0) -> 7 | P44: =ROUND(SUM($AC31:$AZ31)*P$41,0) -> 6 | Q44: =ROUND(SUM($AC31:$AZ31)*Q$41,0) -> 6 | R44: =ROUND(SUM($AC31:$AZ31)*R$41,0) -> 6 | S44: =ROUND(SUM($AC31:$AZ31)*S$41,0) -> 6 | T44: =ROUND(SUM($AC31:$AZ31)*T$41,0) -> 7 | U44: =ROUND(SUM($AC31:$AZ31)*U$41,0) -> 7 | V44: =ROUND(SUM($AC31:$AZ31)*V$41,0) -> 7 | W44: =ROUND(SUM($AC31:$AZ31)*W$41,0) -> 7 | ... AA44: =ROUND(SUM($AC31:$AZ31)*AA$41,0) -> 6 | AB44: =ROUND(SUM($BB31:$BY31)*AB$41,0) -> 5 | AC44: =ROUND(SUM($BB31:$BY31)*AC$41,0) -> 5 | AD44: =ROUND(SUM($BB31:$BY31)*AD$41,0) -> 5 | AE44: =ROUND(SUM($BB31:$BY31)*AE$41,0) -> 7 | AF44: =ROUND(SUM($BB31:$BY31)*AF$41,0) -> 8 | AG44: =ROUND(SUM($BB31:$BY31)*AG$41,0) -> 8 | AH44: =ROUND(SUM($BB31:$BY31)*AH$41,0) -> 8 | AI44: =ROUND(SUM($BB31:$BY31)*AI$41,0) -> 8 | ... AY44: =ROUND(SUM($BB31:$BY31)*AY$41,0) -> 4
C45: client D | D45: =ROUND(SUM($D32:$AA32)*D$41,0) -> 0 | E45: =ROUND(SUM($D32:$AA32)*E$41,0) -> 0 | F45: =ROUND(SUM($D32:$AA32)*F$41,0) -> 0 | G45: =ROUND(SUM($D32:$AA32)*G$41,0) -> 115 | H45: =ROUND(SUM($D32:$AA32)*H$41,0) -> 173 | I45: =ROUND(SUM($D32:$AA32)*I$41,0) -> 173 | J45: =ROUND(SUM($D32:$AA32)*J$41,0) -> 202 | K45: =ROUND(SUM($D32:$AA32)*K$41,0) -> 202 | ... O45: =ROUND(SUM($D32:$AA32)*O$41,0) -> 86 | P45: =ROUND(SUM($AC32:$AZ32)*P$41,0) -> 126 | Q45: =ROUND(SUM($AC32:$AZ32)*Q$41,0) -> 126 | R45: =ROUND(SUM($AC32:$AZ32)*R$41,0) -> 126 | S45: =ROUND(SUM($AC32:$AZ32)*S$41,0) -> 126 | T45: =ROUND(SUM($AC32:$AZ32)*T$41,0) -> 151 | U45: =ROUND(SUM($AC32:$AZ32)*U$41,0) -> 151 | V45: =ROUND(SUM($AC32:$AZ32)*V$41,0) -> 151 | W45: =ROUND(SUM($AC32:$AZ32)*W$41,0) -> 151 | ... AA45: =ROUND(SUM($AC32:$AZ32)*AA$41,0) -> 126 | AB45: =ROUND(SUM($BB32:$BY32)*AB$41,0) -> 106 | AC45: =ROUND(SUM($BB32:$BY32)*AC$41,0) -> 106 | AD45: =ROUND(SUM($BB32:$BY32)*AD$41,0) -> 106 | AE45: =ROUND(SUM($BB32:$BY32)*AE$41,0) -> 133 | AF45: =ROUND(SUM($BB32:$BY32)*AF$41,0) -> 160 | AG45: =ROUND(SUM($BB32:$BY32)*AG$41,0) -> 160 | AH45: =ROUND(SUM($BB32:$BY32)*AH$41,0) -> 160 | AI45: =ROUND(SUM($BB32:$BY32)*AI$41,0) -> 160 | ... AY45: =ROUND(SUM($BB32:$BY32)*AY$41,0) -> 80
C46: client E | D46: =ROUND(SUM($D33:$AA33)*D$41,0) -> 0 | E46: =ROUND(SUM($D33:$AA33)*E$41,0) -> 0 | F46: =ROUND(SUM($D33:$AA33)*F$41,0) -> 0 | G46: =ROUND(SUM($D33:$AA33)*G$41,0) -> 35 | H46: =ROUND(SUM($D33:$AA33)*H$41,0) -> 53 | I46: =ROUND(SUM($D33:$AA33)*I$41,0) -> 53 | J46: =ROUND(SUM($D33:$AA33)*J$41,0) -> 62 | K46: =ROUND(SUM($D33:$AA33)*K$41,0) -> 62 | ... O46: =ROUND(SUM($D33:$AA33)*O$41,0) -> 26 | P46: =ROUND(SUM($AC33:$AZ33)*P$41,0) -> 30 | Q46: =ROUND(SUM($AC33:$AZ33)*Q$41,0) -> 30 | R46: =ROUND(SUM($AC33:$AZ33)*R$41,0) -> 30 | S46: =ROUND(SUM($AC33:$AZ33)*S$41,0) -> 30 | T46: =ROUND(SUM($AC33:$AZ33)*T$41,0) -> 36 | U46: =ROUND(SUM($AC33:$AZ33)*U$41,0) -> 36 | V46: =ROUND(SUM($AC33:$AZ33)*V$41,0) -> 36 | W46: =ROUND(SUM($AC33:$AZ33)*W$41,0) -> 36 | ... AA46: =ROUND(SUM($AC33:$AZ33)*AA$41,0) -> 30 | AB46: =ROUND(SUM($BB33:$BY33)*AB$41,0) -> 34 | AC46: =ROUND(SUM($BB33:$BY33)*AC$41,0) -> 34 | AD46: =ROUND(SUM($BB33:$BY33)*AD$41,0) -> 34 | AE46: =ROUND(SUM($BB33:$BY33)*AE$41,0) -> 43 | AF46: =ROUND(SUM($BB33:$BY33)*AF$41,0) -> 51 | AG46: =ROUND(SUM($BB33:$BY33)*AG$41,0) -> 51 | AH46: =ROUND(SUM($BB33:$BY33)*AH$41,0) -> 51 | AI46: =ROUND(SUM($BB33:$BY33)*AI$41,0) -> 51 | ... AY46: =ROUND(SUM($BB33:$BY33)*AY$41,0) -> 26
D47: =ROUND(SUM($D34:$AA34)*D$41,0) -> 0 | E47: =ROUND(SUM($D34:$AA34)*E$41,0) -> 0 | F47: =ROUND(SUM($D34:$AA34)*F$41,0) -> 0 | G47: =ROUND(SUM($D34:$AA34)*G$41,0) -> 0 | H47: =ROUND(SUM($D34:$AA34)*H$41,0) -> 0 | I47: =ROUND(SUM($D34:$AA34)*I$41,0) -> 0 | J47: =ROUND(SUM($D34:$AA34)*J$41,0) -> 0 | K47: =ROUND(SUM($D34:$AA34)*K$41,0) -> 0 | ... O47: =ROUND(SUM($D34:$AA34)*O$41,0) -> 0 | P47: =ROUND(SUM($AC34:$AZ34)*P$41,0) -> 0 | Q47: =ROUND(SUM($AC34:$AZ34)*Q$41,0) -> 0 | R47: =ROUND(SUM($AC34:$AZ34)*R$41,0) -> 0 | S47: =ROUND(SUM($AC34:$AZ34)*S$41,0) -> 0 | T47: =ROUND(SUM($AC34:$AZ34)*T$41,0) -> 0 | U47: =ROUND(SUM($AC34:$AZ34)*U$41,0) -> 0 | V47: =ROUND(SUM($AC34:$AZ34)*V$41,0) -> 0 | W47: =ROUND(SUM($AC34:$AZ34)*W$41,0) -> 0 | ... AA47: =ROUND(SUM($AC34:$AZ34)*AA$41,0) -> 0 | AB47: =ROUND(SUM($BB34:$BY34)*AB$41,0) -> 0 | AC47: =ROUND(SUM($BB34:$BY34)*AC$41,0) -> 0 | AD47: =ROUND(SUM($BB34:$BY34)*AD$41,0) -> 0 | AE47: =ROUND(SUM($BB34:$BY34)*AE$41,0) -> 0 | AF47: =ROUND(SUM($BB34:$BY34)*AF$41,0) -> 0 | AG47: =ROUND(SUM($BB34:$BY34)*AG$41,0) -> 0 | AH47: =ROUND(SUM($BB34:$BY34)*AH$41,0) -> 0 | AI47: =ROUND(SUM($BB34:$BY34)*AI$41,0) -> 0 | ... AY47: =ROUND(SUM($BB34:$BY34)*AY$41,0) -> 0
...

Sheet CA
B2: CHIFFRE D'AFFAIRES ET COUTS DE PRODUCTION
C4: =YEAR(EDATE(date_début,-12)) -> 2024 | D4: =YEAR(date_début) -> 2025 | Q4: =YEAR(EDATE(date_début,12)) -> 2026 | AD4: =YEAR(EDATE(date_début,24)) -> 2027 | AE4: =YEAR(EDATE(date_début,36)) -> 2028
D5: Jan | E5: Fév | F5: Mar | G5: Avr | H5: Mai | I5: Juin | J5: Juil | K5: Aout | L5: Sept | M5: Oct | N5: Nov | O5: Déc | Q5: Jan | R5: Fév | S5: Mar | T5: Avr | U5: Mai | V5: Juin | W5: Juil | X5: Aout | Y5: Sept | Z5: Oct | AA5: Nov | AB5: Déc
B6: CHIFFRE D'AFFAIRES
B7: Restauration
